Workbook

Sheet How to Play
B2: ⚽ 2026 WORLD CUP — PREDICTION LEAGUE (PRO RULES)
B3: Ganesh • Siddhesh • Aniket USA · Canada · Mexico · June 11 – July 19, 2026
B5: HOW IT WORKS
B6: The idea | C6: Before each match, all three of you type your predicted scoreline. Once the real result is in, points are awarded automatically.
B7: Where to play | C7: The 'Group Stage' tab lists all 72 matches in DATE ORDER, each with its kickoff time and venue, so upcoming games are easy to find. Fill your two numbers per match.
B8: Times | C8: All kickoff times are US Eastern (ET). In Dallas you're Central — subtract 1 hour (a 3:00 PM ET game starts 2:00 PM your time).
B9: Standings | C9: The 'Leaderboard' tab tallies everything live.
B11: SCORING — tiers
B12: Result | C12: Points
B13: Exact scoreline | C13: 5 pts — dead on (said 2–1, finished 2–1).
B14: Right result + right goal difference | C14: 4 pts — correct winner AND margin (said 2–0, finished 3–1).
B15: Right result only | C15: 3 pts — correct winner/draw, wrong margin.
B16: Wrong | C16: 0 pts.
B17: No prediction on a played match | C17: –1 pt — show up or get docked.
B19: THE JOKER
B20: What it is | C20: You each get 8 Jokers for the whole tournament. Put a capital 'J' in your Joker column on a match and your points there DOUBLE. Active Jokers light up gold.
B21: The catch | C21: Jokers only double positive scores. The Leaderboard tracks usage and turns RED if you blow your budget.
B23: BONUS CALLS
B24: Lock in Day 1 | C24: On the 'Bonus Calls' tab you each pick the champion, top scorer, best player and more — up to 25 pts each. They settle at the end and can swing the title.
B26: STRICT MODE
B27: Lock before kickoff | C27: Scorekeeper puts 'L' in the Lock column at kickoff; locked rows go grey. No edits after.
B28: Miss = penalty | C28: Skip a played match, lose a point.
B29: One scorekeeper | C29: One person enters real results (gold columns).
B30: Tie-break | C30: total → most exact (5pt) → Jokers landed → sudden-death predict-off.
B32: STAKES
B33: Loser pays | C33: Bottom of the table buys dinner / runs the next gym setup / owns the bragging rights. Agree before kickoff. 😏
B35: KNOCKOUT STAGE
B36: Auto-fills | C36: Once the groups finish, the 'Knockout' tab fills its team names, dates and scores automatically from the results (the data source handles who advances, including the 8 best third-place teams). Then you predict each knockout scoreline with the same rules. Use the full-time score (if a game goes to penalties, the scoreline is the goals, not the shootout).
B37: Standings tab | C37: Shows all 12 group tables live from the scores so you can see who's advancing as results come in.

Sheet Standings
A1: 📊 GROUP STANDINGS — updates live from the scores
A2: Green = advancing (top 2). Yellow = 3rd place (may still qualify as one of the 8 best). Ranked by Pts → GD → GF; rare exact ties may need a manual head-to-head check.
A4: GROUP A
A5: Pos | B5: Team | C5: Pld | D5: W | E5: D | F5: L | G5: GF | H5: GA | I5: GD | J5: Pts
A6: =IF(SUM($C$6:$C$9)=0,"-",SUMPRODUCT(--(($J$6:$J$9*1000+$I$6:$I$9*10+$G$6:$G$9)>(J6*1000+I6*10+G6)))+1) -> 1 | B6: Mexico | C6: =COUNTIFS('Group Stage'!$E$4:$E$75,"Mexico",'Group Stage'!$H$4:$H$75,"<>")+COUNTIFS('Group Stage'!$F$4:$F$75,"Mexico",'Group Stage'!$H$4:$H$75,"<>") -> 2 | D6: =SUMPRODUCT(('Group Stage'!$E$4:$E$75="Mexico")*('Group Stage'!$H$4:$H$75<>"")*('Group Stage'!$H$4:$H$75>'Group Stage'!$I$4:$I$75))+SUMPRODUCT(('Group Stage'!$F$4:$F$75="Mexico")*('Group Stage'!$H$4:$H$75<>"")*('Group Stage'!$I$4:$I$75>'Group Stage'!$H$4:$H$75)) -> 2 | E6: =SUMPRODUCT((('Group Stage'!$E$4:$E$75="Mexico")+('Group Stage'!$F$4:$F$75="Mexico"))*('Group Stage'!$H$4:$H$75<>"")*('Group Stage'!$H$4:$H$75='Group Stage'!$I$4:$I$75)) -> 0 | F6: =C6-D6-E6 -> 0 | G6: =SUMIFS('Group Stage'!$H$4:$H$75,'Group Stage'!$E$4:$E$75,"Mexico")+SUMIFS('Group Stage'!$I$4:$I$75,'Group Stage'!$F$4:$F$75,"Mexico") -> 3 | H6: =SUMIFS('Group Stage'!$I$4:$I$75,'Group Stage'!$E$4:$E$75,"Mexico")+SUMIFS('Group Stage'!$H$4:$H$75,'Group Stage'!$F$4:$F$75,"Mexico") -> 0 | I6: =G6-H6 -> 3 | J6: =3*D6+E6 -> 6
A7: =IF(SUM($C$6:$C$9)=0,"-",SUMPRODUCT(--(($J$6:$J$9*1000+$I$6:$I$9*10+$G$6:$G$9)>(J7*1000+I7*10+G7)))+1) -> 2 | B7: South Korea | C7: =COUNTIFS('Group Stage'!$E$4:$E$75,"South Korea",'Group Stage'!$H$4:$H$75,"<>")+COUNTIFS('Group Stage'!$F$4:$F$75,"South Korea",'Group Stage'!$H$4:$H$75,"<>") -> 2 | D7: =SUMPRODUCT(('Group Stage'!$E$4:$E$75="South Korea")*('Group Stage'!$H$4:$H$75<>"")*('Group Stage'!$H$4:$H$75>'Group Stage'!$I$4:$I$75))+SUMPRODUCT(('Group Stage'!$F$4:$F$75="South Korea")*('Group Stage'!$H$4:$H$75<>"")*('Group Stage'!$I$4:$I$75>'Group Stage'!$H$4:$H$75)) -> 1 | E7: =SUMPRODUCT((('Group Stage'!$E$4:$E$75="South Korea")+('Group Stage'!$F$4:$F$75="South Korea"))*('Group Stage'!$H$4:$H$75<>"")*('Group Stage'!$H$4:$H$75='Group Stage'!$I$4:$I$75)) -> 0 | F7: =C7-D7-E7 -> 1 | G7: =SUMIFS('Group Stage'!$H$4:$H$75,'Group Stage'!$E$4:$E$75,"South Korea")+SUMIFS('Group Stage'!$I$4:$I$75,'Group Stage'!$F$4:$F$75,"South Korea") -> 2 | H7: =SUMIFS('Group Stage'!$I$4:$I$75,'Group Stage'!$E$4:$E$75,"South Korea")+SUMIFS('Group Stage'!$H$4:$H$75,'Group Stage'!$F$4:$F$75,"South Korea") -> 2 | I7: =G7-H7 -> 0 | J7: =3*D7+E7 -> 3
A8: =IF(SUM($C$6:$C$9)=0,"-",SUMPRODUCT(--(($J$6:$J$9*1000+$I$6:$I$9*10+$G$6:$G$9)>(J8*1000+I8*10+G8)))+1) -> 3 | B8: Czechia | C8: =COUNTIFS('Group Stage'!$E$4:$E$75,"Czechia",'Group Stage'!$H$4:$H$75,"<>")+COUNTIFS('Group Stage'!$F$4:$F$75,"Czechia",'Group Stage'!$H$4:$H$75,"<>") -> 2 | D8: =SUMPRODUCT(('Group Stage'!$E$4:$E$75="Czechia")*('Group Stage'!$H$4:$H$75<>"")*('Group Stage'!$H$4:$H$75>'Group Stage'!$I$4:$I$75))+SUMPRODUCT(('Group Stage'!$F$4:$F$75="Czechia")*('Group Stage'!$H$4:$H$75<>"")*('Group Stage'!$I$4:$I$75>'Group Stage'!$H$4:$H$75)) -> 0 | E8: =SUMPRODUCT((('Group Stage'!$E$4:$E$75="Czechia")+('Group Stage'!$F$4:$F$75="Czechia"))*('Group Stage'!$H$4:$H$75<>"")*('Group Stage'!$H$4:$H$75='Group Stage'!$I$4:$I$75)) -> 1 | F8: =C8-D8-E8 -> 1 | G8: =SUMIFS('Group Stage'!$H$4:$H$75,'Group Stage'!$E$4:$E$75,"Czechia")+SUMIFS('Group Stage'!$I$4:$I$75,'Group Stage'!$F$4:$F$75,"Czechia") -> 2 | H8: =SUMIFS('Group Stage'!$I$4:$I$75,'Group Stage'!$E$4:$E$75,"Czechia")+SUMIFS('Group Stage'!$H$4:$H$75,'Group Stage'!$F$4:$F$75,"Czechia") -> 3 | I8: =G8-H8 -> -1 | J8: =3*D8+E8 -> 1
A9: =IF(SUM($C$6:$C$9)=0,"-",SUMPRODUCT(--(($J$6:$J$9*1000+$I$6:$I$9*10+$G$6:$G$9)>(J9*1000+I9*10+G9)))+1) -> 4 | B9: South Africa | C9: =COUNTIFS('Group Stage'!$E$4:$E$75,"South Africa",'Group Stage'!$H$4:$H$75,"<>")+COUNTIFS('Group Stage'!$F$4:$F$75,"South Africa",'Group Stage'!$H$4:$H$75,"<>") -> 2 | D9: =SUMPRODUCT(('Group Stage'!$E$4:$E$75="South Africa")*('Group Stage'!$H$4:$H$75<>"")*('Group Stage'!$H$4:$H$75>'Group Stage'!$I$4:$I$75))+SUMPRODUCT(('Group Stage'!$F$4:$F$75="South Africa")*('Group Stage'!$H$4:$H$75<>"")*('Group Stage'!$I$4:$I$75>'Group Stage'!$H$4:$H$75)) -> 0 | E9: =SUMPRODUCT((('Group Stage'!$E$4:$E$75="South Africa")+('Group Stage'!$F$4:$F$75="South Africa"))*('Group Stage'!$H$4:$H$75<>"")*('Group Stage'!$H$4:$H$75='Group Stage'!$I$4:$I$75)) -> 1 | F9: =C9-D9-E9 -> 1 | G9: =SUMIFS('Group Stage'!$H$4:$H$75,'Group Stage'!$E$4:$E$75,"South Africa")+SUMIFS('Group Stage'!$I$4:$I$75,'Group Stage'!$F$4:$F$75,"South Africa") -> 1 | H9: =SUMIFS('Group Stage'!$I$4:$I$75,'Group Stage'!$E$4:$E$75,"South Africa")+SUMIFS('Group Stage'!$H$4:$H$75,'Group Stage'!$F$4:$F$75,"South Africa") -> 3 | I9: =G9-H9 -> -2 | J9: =3*D9+E9 -> 1
A11: GROUP B
A12: Pos | B12: Team | C12: Pld | D12: W | E12: D | F12: L | G12: GF | H12: GA | I12: GD | J12: Pts
A13: =IF(SUM($C$13:$C$16)=0,"-",SUMPRODUCT(--(($J$13:$J$16*1000+$I$13:$I$16*10+$G$13:$G$16)>(J13*1000+I13*10+G13)))+1) -> 1 | B13: Canada | C13: =COUNTIFS('Group Stage'!$E$4:$E$75,"Canada",'Group Stage'!$H$4:$H$75,"<>")+COUNTIFS('Group Stage'!$F$4:$F$75,"Canada",'Group Stage'!$H$4:$H$75,"<>") -> 2 | D13: =SUMPRODUCT(('Group Stage'!$E$4:$E$75="Canada")*('Group Stage'!$H$4:$H$75<>"")*('Group Stage'!$H$4:$H$75>'Group Stage'!$I$4:$I$75))+SUMPRODUCT(('Group Stage'!$F$4:$F$75="Canada")*('Group Stage'!$H$4:$H$75<>"")*('Group Stage'!$I$4:$I$75>'Group Stage'!$H$4:$H$75)) -> 1 | E13: =SUMPRODUCT((('Group Stage'!$E$4:$E$75="Canada")+('Group Stage'!$F$4:$F$75="Canada"))*('Group Stage'!$H$4:$H$75<>"")*('Group Stage'!$H$4:$H$75='Group Stage'!$I$4:$I$75)) -> 1 | F13: =C13-D13-E13 -> 0 | G13: =SUMIFS('Group Stage'!$H$4:$H$75,'Group Stage'!$E$4:$E$75,"Canada")+SUMIFS('Group Stage'!$I$4:$I$75,'Group Stage'!$F$4:$F$75,"Canada") -> 7 | H13: =SUMIFS('Group Stage'!$I$4:$I$75,'Group Stage'!$E$4:$E$75,"Canada")+SUMIFS('Group Stage'!$H$4:$H$75,'Group Stage'!$F$4:$F$75,"Canada") -> 1 | I13: =G13-H13 -> 6 | J13: =3*D13+E13 -> 4
A14: =IF(SUM($C$13:$C$16)=0,"-",SUMPRODUCT(--(($J$13:$J$16*1000+$I$13:$I$16*10+$G$13:$G$16)>(J14*1000+I14*10+G14)))+1) -> 3 | B14: Bosnia-Herzegovina | C14: =COUNTIFS('Group Stage'!$E$4:$E$75,"Bosnia-Herzegovina",'Group Stage'!$H$4:$H$75,"<>")+COUNTIFS('Group Stage'!$F$4:$F$75,"Bosnia-Herzegovina",'Group Stage'!$H$4:$H$75,"<>") -> 2 | D14: =SUMPRODUCT(('Group Stage'!$E$4:$E$75="Bosnia-Herzegovina")*('Group Stage'!$H$4:$H$75<>"")*('Group Stage'!$H$4:$H$75>'Group Stage'!$I$4:$I$75))+SUMPRODUCT(('Group Stage'!$F$4:$F$75="Bosnia-Herzegovina")*('Group Stage'!$H$4:$H$75<>"")*('Group Stage'!$I$4:$I$75>'Group Stage'!$H$4:$H$75)) -> 0 | E14: =SUMPRODUCT((('Group Stage'!$E$4:$E$75="Bosnia-Herzegovina")+('Group Stage'!$F$4:$F$75="Bosnia-Herzegovina"))*('Group Stage'!$H$4:$H$75<>"")*('Group Stage'!$H$4:$H$75='Group Stage'!$I$4:$I$75)) -> 1 | F14: =C14-D14-E14 -> 1 | G14: =SUMIFS('Group Stage'!$H$4:$H$75,'Group Stage'!$E$4:$E$75,"Bosnia-Herzegovina")+SUMIFS('Group Stage'!$I$4:$I$75,'Group Stage'!$F$4:$F$75,"Bosnia-Herzegovina") -> 2 | H14: =SUMIFS('Group Stage'!$I$4:$I$75,'Group Stage'!$E$4:$E$75,"Bosnia-Herzegovina")+SUMIFS('Group Stage'!$H$4:$H$75,'Group Stage'!$F$4:$F$75,"Bosnia-Herzegovina") -> 5 | I14: =G14-H14 -> -3 | J14: =3*D14+E14 -> 1
A15: =IF(SUM($C$13:$C$16)=0,"-",SUMPRODUCT(--(($J$13:$J$16*1000+$I$13:$I$16*10+$G$13:$G$16)>(J15*1000+I15*10+G15)))+1) -> 4 | B15: Qatar | C15: =COUNTIFS('Group Stage'!$E$4:$E$75,"Qatar",'Group Stage'!$H$4:$H$75,"<>")+COUNTIFS('Group Stage'!$F$4:$F$75,"Qatar",'Group Stage'!$H$4:$H$75,"<>") -> 2 | D15: =SUMPRODUCT(('Group Stage'!$E$4:$E$75="Qatar")*('Group Stage'!$H$4:$H$75<>"")*('Group Stage'!$H$4:$H$75>'Group Stage'!$I$4:$I$75))+SUMPRODUCT(('Group Stage'!$F$4:$F$75="Qatar")*('Group Stage'!$H$4:$H$75<>"")*('Group Stage'!$I$4:$I$75>'Group Stage'!$H$4:$H$75)) -> 0 | E15: =SUMPRODUCT((('Group Stage'!$E$4:$E$75="Qatar")+('Group Stage'!$F$4:$F$75="Qatar"))*('Group Stage'!$H$4:$H$75<>"")*('Group Stage'!$H$4:$H$75='Group Stage'!$I$4:$I$75)) -> 1 | F15: =C15-D15-E15 -> 1 | G15: =SUMIFS('Group Stage'!$H$4:$H$75,'Group Stage'!$E$4:$E$75,"Qatar")+SUMIFS('Group Stage'!$I$4:$I$75,'Group Stage'!$F$4:$F$75,"Qatar") -> 1 | H15: =SUMIFS('Group Stage'!$I$4:$I$75,'Group Stage'!$E$4:$E$75,"Qatar")+SUMIFS('Group Stage'!$H$4:$H$75,'Group Stage'!$F$4:$F$75,"Qatar") -> 7 | I15: =G15-H15 -> -6 | J15: =3*D15+E15 -> 1
A16: =IF(SUM($C$13:$C$16)=0,"-",SUMPRODUCT(--(($J$13:$J$16*1000+$I$13:$I$16*10+$G$13:$G$16)>(J16*1000+I16*10+G16)))+1) -> 2 | B16: Switzerland | C16: =COUNTIFS('Group Stage'!$E$4:$E$75,"Switzerland",'Group Stage'!$H$4:$H$75,"<>")+COUNTIFS('Group Stage'!$F$4:$F$75,"Switzerland",'Group Stage'!$H$4:$H$75,"<>") -> 2 | D16: =SUMPRODUCT(('Group Stage'!$E$4:$E$75="Switzerland")*('Group Stage'!$H$4:$H$75<>"")*('Group Stage'!$H$4:$H$75>'Group Stage'!$I$4:$I$75))+SUMPRODUCT(('Group Stage'!$F$4:$F$75="Switzerland")*('Group Stage'!$H$4:$H$75<>"")*('Group Stage'!$I$4:$I$75>'Group Stage'!$H$4:$H$75)) -> 1 | E16: =SUMPRODUCT((('Group Stage'!$E$4:$E$75="Switzerland")+('Group Stage'!$F$4:$F$75="Switzerland"))*('Group Stage'!$H$4:$H$75<>"")*('Group Stage'!$H$4:$H$75='Group Stage'!$I$4:$I$75)) -> 1 | F16: =C16-D16-E16 -> 0 | G16: =SUMIFS('Group Stage'!$H$4:$H$75,'Group Stage'!$E$4:$E$75,"Switzerland")+SUMIFS('Group Stage'!$I$4:$I$75,'Group Stage'!$F$4:$F$75,"Switzerland") -> 5 | H16: =SUMIFS('Group Stage'!$I$4:$I$75,'Group Stage'!$E$4:$E$75,"Switzerland")+SUMIFS('Group Stage'!$H$4:$H$75,'Group Stage'!$F$4:$F$75,"Switzerland") -> 2 | I16: =G16-H16 -> 3 | J16: =3*D16+E16 -> 4
A18: GROUP C
A19: Pos | B19: Team | C19: Pld | D19: W | E19: D | F19: L | G19: GF | H19: GA | I19: GD | J19: Pts
A20: =IF(SUM($C$20:$C$23)=0,"-",SUMPRODUCT(--(($J$20:$J$23*1000+$I$20:$I$23*10+$G$20:$G$23)>(J20*1000+I20*10+G20)))+1) -> 1 | B20: Brazil | C20: =COUNTIFS('Group Stage'!$E$4:$E$75,"Brazil",'Group Stage'!$H$4:$H$75,"<>")+COUNTIFS('Group Stage'!$F$4:$F$75,"Brazil",'Group Stage'!$H$4:$H$75,"<>") -> 2 | D20: =SUMPRODUCT(('Group Stage'!$E$4:$E$75="Brazil")*('Group Stage'!$H$4:$H$75<>"")*('Group Stage'!$H$4:$H$75>'Group Stage'!$I$4:$I$75))+SUMPRODUCT(('Group Stage'!$F$4:$F$75="Brazil")*('Group Stage'!$H$4:$H$75<>"")*('Group Stage'!$I$4:$I$75>'Group Stage'!$H$4:$H$75)) -> 1 | E20: =SUMPRODUCT((('Group Stage'!$E$4:$E$75="Brazil")+('Group Stage'!$F$4:$F$75="Brazil"))*('Group Stage'!$H$4:$H$75<>"")*('Group Stage'!$H$4:$H$75='Group Stage'!$I$4:$I$75)) -> 1 | F20: =C20-D20-E20 -> 0 | G20: =SUMIFS('Group Stage'!$H$4:$H$75,'Group Stage'!$E$4:$E$75,"Brazil")+SUMIFS('Group Stage'!$I$4:$I$75,'Group Stage'!$F$4:$F$75,"Brazil") -> 4 | H20: =SUMIFS('Group Stage'!$I$4:$I$75,'Group Stage'!$E$4:$E$75,"Brazil")+SUMIFS('Group Stage'!$H$4:$H$75,'Group Stage'!$F$4:$F$75,"Brazil") -> 1 | I20: =G20-H20 -> 3 | J20: =3*D20+E20 -> 4
A21: =IF(SUM($C$20:$C$23)=0,"-",SUMPRODUCT(--(($J$20:$J$23*1000+$I$20:$I$23*10+$G$20:$G$23)>(J21*1000+I21*10+G21)))+1) -> 2 | B21: Morocco | C21: =COUNTIFS('Group Stage'!$E$4:$E$75,"Morocco",'Group Stage'!$H$4:$H$75,"<>")+COUNTIFS('Group Stage'!$F$4:$F$75,"Morocco",'Group Stage'!$H$4:$H$75,"<>") -> 2 | D21: =SUMPRODUCT(('Group Stage'!$E$4:$E$75="Morocco")*('Group Stage'!$H$4:$H$75<>"")*('Group Stage'!$H$4:$H$75>'Group Stage'!$I$4:$I$75))+SUMPRODUCT(('Group Stage'!$F$4:$F$75="Morocco")*('Group Stage'!$H$4:$H$75<>"")*('Group Stage'!$I$4:$I$75>'Group Stage'!$H$4:$H$75)) -> 1 | E21: =SUMPRODUCT((('Group Stage'!$E$4:$E$75="Morocco")+('Group Stage'!$F$4:$F$75="Morocco"))*('Group Stage'!$H$4:$H$75<>"")*('Group Stage'!$H$4:$H$75='Group Stage'!$I$4:$I$75)) -> 1 | F21: =C21-D21-E21 -> 0 | G21: =SUMIFS('Group Stage'!$H$4:$H$75,'Group Stage'!$E$4:$E$75,"Morocco")+SUMIFS('Group Stage'!$I$4:$I$75,'Group Stage'!$F$4:$F$75,"Morocco") -> 2 | H21: =SUMIFS('Group Stage'!$I$4:$I$75,'Group Stage'!$E$4:$E$75,"Morocco")+SUMIFS('Group Stage'!$H$4:$H$75,'Group Stage'!$F$4:$F$75,"Morocco") -> 1 | I21: =G21-H21 -> 1 | J21: =3*D21+E21 -> 4
A22: =IF(SUM($C$20:$C$23)=0,"-",SUMPRODUCT(--(($J$20:$J$23*1000+$I$20:$I$23*10+$G$20:$G$23)>(J22*1000+I22*10+G22)))+1) -> 3 | B22: Scotland | C22: =COUNTIFS('Group Stage'!$E$4:$E$75,"Scotland",'Group Stage'!$H$4:$H$75,"<>")+COUNTIFS('Group Stage'!$F$4:$F$75,"Scotland",'Group Stage'!$H$4:$H$75,"<>") -> 2 | D22: =SUMPRODUCT(('Group Stage'!$E$4:$E$75="Scotland")*('Group Stage'!$H$4:$H$75<>"")*('Group Stage'!$H$4:$H$75>'Group Stage'!$I$4:$I$75))+SUMPRODUCT(('Group Stage'!$F$4:$F$75="Scotland")*('Group Stage'!$H$4:$H$75<>"")*('Group Stage'!$I$4:$I$75>'Group Stage'!$H$4:$H$75)) -> 1 | E22: =SUMPRODUCT((('Group Stage'!$E$4:$E$75="Scotland")+('Group Stage'!$F$4:$F$75="Scotland"))*('Group Stage'!$H$4:$H$75<>"")*('Group Stage'!$H$4:$H$75='Group Stage'!$I$4:$I$75)) -> 0 | F22: =C22-D22-E22 -> 1 | G22: =SUMIFS('Group Stage'!$H$4:$H$75,'Group Stage'!$E$4:$E$75,"Scotland")+SUMIFS('Group Stage'!$I$4:$I$75,'Group Stage'!$F$4:$F$75,"Scotland") -> 1 | H22: =SUMIFS('Group Stage'!$I$4:$I$75,'Group Stage'!$E$4:$E$75,"Scotland")+SUMIFS('Group Stage'!$H$4:$H$75,'Group Stage'!$F$4:$F$75,"Scotland") -> 1 | I22: =G22-H22 -> 0 | J22: =3*D22+E22 -> 3
A23: =IF(SUM($C$20:$C$23)=0,"-",SUMPRODUCT(--(($J$20:$J$23*1000+$I$20:$I$23*10+$G$20:$G$23)>(J23*1000+I23*10+G23)))+1) -> 4 | B23: Haiti | C23: =COUNTIFS('Group Stage'!$E$4:$E$75,"Haiti",'Group Stage'!$H$4:$H$75,"<>")+COUNTIFS('Group Stage'!$F$4:$F$75,"Haiti",'Group Stage'!$H$4:$H$75,"<>") -> 2 | D23: =SUMPRODUCT(('Group Stage'!$E$4:$E$75="Haiti")*('Group Stage'!$H$4:$H$75<>"")*('Group Stage'!$H$4:$H$75>'Group Stage'!$I$4:$I$75))+SUMPRODUCT(('Group Stage'!$F$4:$F$75="Haiti")*('Group Stage'!$H$4:$H$75<>"")*('Group Stage'!$I$4:$I$75>'Group Stage'!$H$4:$H$75)) -> 0 | E23: =SUMPRODUCT((('Group Stage'!$E$4:$E$75="Haiti")+('Group Stage'!$F$4:$F$75="Haiti"))*('Group Stage'!$H$4:$H$75<>"")*('Group Stage'!$H$4:$H$75='Group Stage'!$I$4:$I$75)) -> 0 | F23: =C23-D23-E23 -> 2 | G23: =SUMIFS('Group Stage'!$H$4:$H$75,'Group Stage'!$E$4:$E$75,"Haiti")+SUMIFS('Group Stage'!$I$4:$I$75,'Group Stage'!$F$4:$F$75,"Haiti") -> 0 | H23: =SUMIFS('Group Stage'!$I$4:$I$75,'Group Stage'!$E$4:$E$75,"Haiti")+SUMIFS('Group Stage'!$H$4:$H$75,'Group Stage'!$F$4:$F$75,"Haiti") -> 4 | I23: =G23-H23 -> -4 | J23: =3*D23+E23 -> 0
A25: GROUP D
A26: Pos | B26: Team | C26: Pld | D26: W | E26: D | F26: L | G26: GF | H26: GA | I26: GD | J26: Pts
A27: =IF(SUM($C$27:$C$30)=0,"-",SUMPRODUCT(--(($J$27:$J$30*1000+$I$27:$I$30*10+$G$27:$G$30)>(J27*1000+I27*10+G27)))+1) -> 1 | B27: United States | C27: =COUNTIFS('Group Stage'!$E$4:$E$75,"United States",'Group Stage'!$H$4:$H$75,"<>")+COUNTIFS('Group Stage'!$F$4:$F$75,"United States",'Group Stage'!$H$4:$H$75,"<>") -> 2 | D27: =SUMPRODUCT(('Group Stage'!$E$4:$E$75="United States")*('Group Stage'!$H$4:$H$75<>"")*('Group Stage'!$H$4:$H$75>'Group Stage'!$I$4:$I$75))+SUMPRODUCT(('Group Stage'!$F$4:$F$75="United States")*('Group Stage'!$H$4:$H$75<>"")*('Group Stage'!$I$4:$I$75>'Group Stage'!$H$4:$H$75)) -> 2 | E27: =SUMPRODUCT((('Group Stage'!$E$4:$E$75="United States")+('Group Stage'!$F$4:$F$75="United States"))*('Group Stage'!$H$4:$H$75<>"")*('Group Stage'!$H$4:$H$75='Group Stage'!$I$4:$I$75)) -> 0 | F27: =C27-D27-E27 -> 0 | G27: =SUMIFS('Group Stage'!$H$4:$H$75,'Group Stage'!$E$4:$E$75,"United States")+SUMIFS('Group Stage'!$I$4:$I$75,'Group Stage'!$F$4:$F$75,"United States") -> 6 | H27: =SUMIFS('Group Stage'!$I$4:$I$75,'Group Stage'!$E$4:$E$75,"United States")+SUMIFS('Group Stage'!$H$4:$H$75,'Group Stage'!$F$4:$F$75,"United States") -> 1 | I27: =G27-H27 -> 5 | J27: =3*D27+E27 -> 6
A28: =IF(SUM($C$27:$C$30)=0,"-",SUMPRODUCT(--(($J$27:$J$30*1000+$I$27:$I$30*10+$G$27:$G$30)>(J28*1000+I28*10+G28)))+1) -> 3 | B28: Paraguay | C28: =COUNTIFS('Group Stage'!$E$4:$E$75,"Paraguay",'Group Stage'!$H$4:$H$75,"<>")+COUNTIFS('Group Stage'!$F$4:$F$75,"Paraguay",'Group Stage'!$H$4:$H$75,"<>") -> 2 | D28: =SUMPRODUCT(('Group Stage'!$E$4:$E$75="Paraguay")*('Group Stage'!$H$4:$H$75<>"")*('Group Stage'!$H$4:$H$75>'Group Stage'!$I$4:$I$75))+SUMPRODUCT(('Group Stage'!$F$4:$F$75="Paraguay")*('Group Stage'!$H$4:$H$75<>"")*('Group Stage'!$I$4:$I$75>'Group Stage'!$H$4:$H$75)) -> 1 | E28: =SUMPRODUCT((('Group Stage'!$E$4:$E$75="Paraguay")+('Group Stage'!$F$4:$F$75="Paraguay"))*('Group Stage'!$H$4:$H$75<>"")*('Group Stage'!$H$4:$H$75='Group Stage'!$I$4:$I$75)) -> 0 | F28: =C28-D28-E28 -> 1 | G28: =SUMIFS('Group Stage'!$H$4:$H$75,'Group Stage'!$E$4:$E$75,"Paraguay")+SUMIFS('Group Stage'!$I$4:$I$75,'Group Stage'!$F$4:$F$75,"Paraguay") -> 2 | H28: =SUMIFS('Group Stage'!$I$4:$I$75,'Group Stage'!$E$4:$E$75,"Paraguay")+SUMIFS('Group Stage'!$H$4:$H$75,'Group Stage'!$F$4:$F$75,"Paraguay") -> 4 | I28: =G28-H28 -> -2 | J28: =3*D28+E28 -> 3
A29: =IF(SUM($C$27:$C$30)=0,"-",SUMPRODUCT(--(($J$27:$J$30*1000+$I$27:$I$30*10+$G$27:$G$30)>(J29*1000+I29*10+G29)))+1) -> 2 | B29: Australia | C29: =COUNTIFS('Group Stage'!$E$4:$E$75,"Australia",'Group Stage'!$H$4:$H$75,"<>")+COUNTIFS('Group Stage'!$F$4:$F$75,"Australia",'Group Stage'!$H$4:$H$75,"<>") -> 2 | D29: =SUMPRODUCT(('Group Stage'!$E$4:$E$75="Australia")*('Group Stage'!$H$4:$H$75<>"")*('Group Stage'!$H$4:$H$75>'Group Stage'!$I$4:$I$75))+SUMPRODUCT(('Group Stage'!$F$4:$F$75="Australia")*('Group Stage'!$H$4:$H$75<>"")*('Group Stage'!$I$4:$I$75>'Group Stage'!$H$4:$H$75)) -> 1 | E29: =SUMPRODUCT((('Group Stage'!$E$4:$E$75="Australia")+('Group Stage'!$F$4:$F$75="Australia"))*('Group Stage'!$H$4:$H$75<>"")*('Group Stage'!$H$4:$H$75='Group Stage'!$I$4:$I$75)) -> 0 | F29: =C29-D29-E29 -> 1 | G29: =SUMIFS('Group Stage'!$H$4:$H$75,'Group Stage'!$E$4:$E$75,"Australia")+SUMIFS('Group Stage'!$I$4:$I$75,'Group Stage'!$F$4:$F$75,"Australia") -> 2 | H29: =SUMIFS('Group Stage'!$I$4:$I$75,'Group Stage'!$E$4:$E$75,"Australia")+SUMIFS('Group Stage'!$H$4:$H$75,'Group Stage'!$F$4:$F$75,"Australia") -> 2 | I29: =G29-H29 -> 0 | J29: =3*D29+E29 -> 3
A30: =IF(SUM($C$27:$C$30)=0,"-",SUMPRODUCT(--(($J$27:$J$30*1000+$I$27:$I$30*10+$G$27:$G$30)>(J30*1000+I30*10+G30)))+1) -> 4 | B30: Türkiye | C30: =COUNTIFS('Group Stage'!$E$4:$E$75,"Türkiye",'Group Stage'!$H$4:$H$75,"<>")+COUNTIFS('Group Stage'!$F$4:$F$75,"Türkiye",'Group Stage'!$H$4:$H$75,"<>") -> 2 | D30: =SUMPRODUCT(('Group Stage'!$E$4:$E$75="Türkiye")*('Group Stage'!$H$4:$H$75<>"")*('Group Stage'!$H$4:$H$75>'Group Stage'!$I$4:$I$75))+SUMPRODUCT(('Group Stage'!$F$4:$F$75="Türkiye")*('Group Stage'!$H$4:$H$75<>"")*('Group Stage'!$I$4:$I$75>'Group Stage'!$H$4:$H$75)) -> 0 | E30: =SUMPRODUCT((('Group Stage'!$E$4:$E$75="Türkiye")+('Group Stage'!$F$4:$F$75="Türkiye"))*('Group Stage'!$H$4:$H$75<>"")*('Group Stage'!$H$4:$H$75='Group Stage'!$I$4:$I$75)) -> 0 | F30: =C30-D30-E30 -> 2 | G30: =SUMIFS('Group Stage'!$H$4:$H$75,'Group Stage'!$E$4:$E$75,"Türkiye")+SUMIFS('Group Stage'!$I$4:$I$75,'Group Stage'!$F$4:$F$75,"Türkiye") -> 0 | H30: =SUMIFS('Group Stage'!$I$4:$I$75,'Group Stage'!$E$4:$E$75,"Türkiye")+SUMIFS('Group Stage'!$H$4:$H$75,'Group Stage'!$F$4:$F$75,"Türkiye") -> 3 | I30: =G30-H30 -> -3 | J30: =3*D30+E30 -> 0
A32: GROUP E
A33: Pos | B33: Team | C33: Pld | D33: W | E33: D | F33: L | G33: GF | H33: GA | I33: GD | J33: Pts
A34: =IF(SUM($C$34:$C$37)=0,"-",SUMPRODUCT(--(($J$34:$J$37*1000+$I$34:$I$37*10+$G$34:$G$37)>(J34*1000+I34*10+G34)))+1) -> 1 | B34: Germany | C34: =COUNTIFS('Group Stage'!$E$4:$E$75,"Germany",'Group Stage'!$H$4:$H$75,"<>")+COUNTIFS('Group Stage'!$F$4:$F$75,"Germany",'Group Stage'!$H$4:$H$75,"<>") -> 2 | D34: =SUMPRODUCT(('Group Stage'!$E$4:$E$75="Germany")*('Group Stage'!$H$4:$H$75<>"")*('Group Stage'!$H$4:$H$75>'Group Stage'!$I$4:$I$75))+SUMPRODUCT(('Group Stage'!$F$4:$F$75="Germany")*('Group Stage'!$H$4:$H$75<>"")*('Group Stage'!$I$4:$I$75>'Group Stage'!$H$4:$H$75)) -> 2 | E34: =SUMPRODUCT((('Group Stage'!$E$4:$E$75="Germany")+('Group Stage'!$F$4:$F$75="Germany"))*('Group Stage'!$H$4:$H$75<>"")*('Group Stage'!$H$4:$H$75='Group Stage'!$I$4:$I$75)) -> 0 | F34: =C34-D34-E34 -> 0 | G34: =SUMIFS('Group Stage'!$H$4:$H$75,'Group Stage'!$E$4:$E$75,"Germany")+SUMIFS('Group Stage'!$I$4:$I$75,'Group Stage'!$F$4:$F$75,"Germany") -> 9 | H34: =SUMIFS('Group Stage'!$I$4:$I$75,'Group Stage'!$E$4:$E$75,"Germany")+SUMIFS('Group Stage'!$H$4:$H$75,'Group Stage'!$F$4:$F$75,"Germany") -> 2 | I34: =G34-H34 -> 7 | J34: =3*D34+E34 -> 6
A35: =IF(SUM($C$34:$C$37)=0,"-",SUMPRODUCT(--(($J$34:$J$37*1000+$I$34:$I$37*10+$G$34:$G$37)>(J35*1000+I35*10+G35)))+1) -> 4 | B35: Curaçao | C35: =COUNTIFS('Group Stage'!$E$4:$E$75,"Curaçao",'Group Stage'!$H$4:$H$75,"<>")+COUNTIFS('Group Stage'!$F$4:$F$75,"Curaçao",'Group Stage'!$H$4:$H$75,"<>") -> 2 | D35: =SUMPRODUCT(('Group Stage'!$E$4:$E$75="Curaçao")*('Group Stage'!$H$4:$H$75<>"")*('Group Stage'!$H$4:$H$75>'Group Stage'!$I$4:$I$75))+SUMPRODUCT(('Group Stage'!$F$4:$F$75="Curaçao")*('Group Stage'!$H$4:$H$75<>"")*('Group Stage'!$I$4:$I$75>'Group Stage'!$H$4:$H$75)) -> 0 | E35: =SUMPRODUCT((('Group Stage'!$E$4:$E$75="Curaçao")+('Group Stage'!$F$4:$F$75="Curaçao"))*('Group Stage'!$H$4:$H$75<>"")*('Group Stage'!$H$4:$H$75='Group Stage'!$I$4:$I$75)) -> 1 | F35: =C35-D35-E35 -> 1 | G35: =SUMIFS('Group Stage'!$H$4:$H$75,'Group Stage'!$E$4:$E$75,"Curaçao")+SUMIFS('Group Stage'!$I$4:$I$75,'Group Stage'!$F$4:$F$75,"Curaçao") -> 1 | H35: =SUMIFS('Group Stage'!$I$4:$I$75,'Group Stage'!$E$4:$E$75,"Curaçao")+SUMIFS('Group Stage'!$H$4:$H$75,'Group Stage'!$F$4:$F$75,"Curaçao") -> 7 | I35: =G35-H35 -> -6 | J35: =3*D35+E35 -> 1
A36: =IF(SUM($C$34:$C$37)=0,"-",SUMPRODUCT(--(($J$34:$J$37*1000+$I$34:$I$37*10+$G$34:$G$37)>(J36*1000+I36*10+G36)))+1) -> 2 | B36: Ivory Coast | C36: =COUNTIFS('Group Stage'!$E$4:$E$75,"Ivory Coast",'Group Stage'!$H$4:$H$75,"<>")+COUNTIFS('Group Stage'!$F$4:$F$75,"Ivory Coast",'Group Stage'!$H$4:$H$75,"<>") -> 2 | D36: =SUMPRODUCT(('Group Stage'!$E$4:$E$75="Ivory Coast")*('Group Stage'!$H$4:$H$75<>"")*('Group Stage'!$H$4:$H$75>'Group Stage'!$I$4:$I$75))+SUMPRODUCT(('Group Stage'!$F$4:$F$75="Ivory Coast")*('Group Stage'!$H$4:$H$75<>"")*('Group Stage'!$I$4:$I$75>'Group Stage'!$H$4:$H$75)) -> 1 | E36: =SUMPRODUCT((('Group Stage'!$E$4:$E$75="Ivory Coast")+('Group Stage'!$F$4:$F$75="Ivory Coast"))*('Group Stage'!$H$4:$H$75<>"")*('Group Stage'!$H$4:$H$75='Group Stage'!$I$4:$I$75)) -> 0 | F36: =C36-D36-E36 -> 1 | G36: =SUMIFS('Group Stage'!$H$4:$H$75,'Group Stage'!$E$4:$E$75,"Ivory Coast")+SUMIFS('Group Stage'!$I$4:$I$75,'Group Stage'!$F$4:$F$75,"Ivory Coast") -> 2 | H36: =SUMIFS('Group Stage'!$I$4:$I$75,'Group Stage'!$E$4:$E$75,"Ivory Coast")+SUMIFS('Group Stage'!$H$4:$H$75,'Group Stage'!$F$4:$F$75,"Ivory Coast") -> 2 | I36: =G36-H36 -> 0 | J36: =3*D36+E36 -> 3
A37: =IF(SUM($C$34:$C$37)=0,"-",SUMPRODUCT(--(($J$34:$J$37*1000+$I$34:$I$37*10+$G$34:$G$37)>(J37*1000+I37*10+G37)))+1) -> 3 | B37: Ecuador | C37: =COUNTIFS('Group Stage'!$E$4:$E$75,"Ecuador",'Group Stage'!$H$4:$H$75,"<>")+COUNTIFS('Group Stage'!$F$4:$F$75,"Ecuador",'Group Stage'!$H$4:$H$75,"<>") -> 2 | D37: =SUMPRODUCT(('Group Stage'!$E$4:$E$75="Ecuador")*('Group Stage'!$H$4:$H$75<>"")*('Group Stage'!$H$4:$H$75>'Group Stage'!$I$4:$I$75))+SUMPRODUCT(('Group Stage'!$F$4:$F$75="Ecuador")*('Group Stage'!$H$4:$H$75<>"")*('Group Stage'!$I$4:$I$75>'Group Stage'!$H$4:$H$75)) -> 0 | E37: =SUMPRODUCT((('Group Stage'!$E$4:$E$75="Ecuador")+('Group Stage'!$F$4:$F$75="Ecuador"))*('Group Stage'!$H$4:$H$75<>"")*('Group Stage'!$H$4:$H$75='Group Stage'!$I$4:$I$75)) -> 1 | F37: =C37-D37-E37 -> 1 | G37: =SUMIFS('Group Stage'!$H$4:$H$75,'Group Stage'!$E$4:$E$75,"Ecuador")+SUMIFS('Group Stage'!$I$4:$I$75,'Group Stage'!$F$4:$F$75,"Ecuador") -> 0 | H37: =SUMIFS('Group Stage'!$I$4:$I$75,'Group Stage'!$E$4:$E$75,"Ecuador")+SUMIFS('Group Stage'!$H$4:$H$75,'Group Stage'!$F$4:$F$75,"Ecuador") -> 1 | I37: =G37-H37 -> -1 | J37: =3*D37+E37 -> 1
A39: GROUP F
A40: Pos | B40: Team | C40: Pld | D40: W | E40: D | F40: L | G40: GF | H40: GA | I40: GD | J40: Pts
A41: =IF(SUM($C$41:$C$44)=0,"-",SUMPRODUCT(--(($J$41:$J$44*1000+$I$41:$I$44*10+$G$41:$G$44)>(J41*1000+I41*10+G41)))+1) -> 1 | B41: Netherlands | C41: =COUNTIFS('Group Stage'!$E$4:$E$75,"Netherlands",'Group Stage'!$H$4:$H$75,"<>")+COUNTIFS('Group Stage'!$F$4:$F$75,"Netherlands",'Group Stage'!$H$4:$H$75,"<>") -> 2 | D41: =SUMPRODUCT(('Group Stage'!$E$4:$E$75="Netherlands")*('Group Stage'!$H$4:$H$75<>"")*('Group Stage'!$H$4:$H$75>'Group Stage'!$I$4:$I$75))+SUMPRODUCT(('Group Stage'!$F$4:$F$75="Netherlands")*('Group Stage'!$H$4:$H$75<>"")*('Group Stage'!$I$4:$I$75>'Group Stage'!$H$4:$H$75)) -> 1 | E41: =SUMPRODUCT((('Group Stage'!$E$4:$E$75="Netherlands")+('Group Stage'!$F$4:$F$75="Netherlands"))*('Group Stage'!$H$4:$H$75<>"")*('Group Stage'!$H$4:$H$75='Group Stage'!$I$4:$I$75)) -> 1 | F41: =C41-D41-E41 -> 0 | G41: =SUMIFS('Group Stage'!$H$4:$H$75,'Group Stage'!$E$4:$E$75,"Netherlands")+SUMIFS('Group Stage'!$I$4:$I$75,'Group Stage'!$F$4:$F$75,"Netherlands") -> 7 | H41: =SUMIFS('Group Stage'!$I$4:$I$75,'Group Stage'!$E$4:$E$75,"Netherlands")+SUMIFS('Group Stage'!$H$4:$H$75,'Group Stage'!$F$4:$F$75,"Netherlands") -> 3 | I41: =G41-H41 -> 4 | J41: =3*D41+E41 -> 4
A42: =IF(SUM($C$41:$C$44)=0,"-",SUMPRODUCT(--(($J$41:$J$44*1000+$I$41:$I$44*10+$G$41:$G$44)>(J42*1000+I42*10+G42)))+1) -> 2 | B42: Japan | C42: =COUNTIFS('Group Stage'!$E$4:$E$75,"Japan",'Group Stage'!$H$4:$H$75,"<>")+COUNTIFS('Group Stage'!$F$4:$F$75,"Japan",'Group Stage'!$H$4:$H$75,"<>") -> 2 | D42: =SUMPRODUCT(('Group Stage'!$E$4:$E$75="Japan")*('Group Stage'!$H$4:$H$75<>"")*('Group Stage'!$H$4:$H$75>'Group Stage'!$I$4:$I$75))+SUMPRODUCT(('Group Stage'!$F$4:$F$75="Japan")*('Group Stage'!$H$4:$H$75<>"")*('Group Stage'!$I$4:$I$75>'Group Stage'!$H$4:$H$75)) -> 1 | E42: =SUMPRODUCT((('Group Stage'!$E$4:$E$75="Japan")+('Group Stage'!$F$4:$F$75="Japan"))*('Group Stage'!$H$4:$H$75<>"")*('Group Stage'!$H$4:$H$75='Group Stage'!$I$4:$I$75)) -> 1 | F42: =C42-D42-E42 -> 0 | G42: =SUMIFS('Group Stage'!$H$4:$H$75,'Group Stage'!$E$4:$E$75,"Japan")+SUMIFS('Group Stage'!$I$4:$I$75,'Group Stage'!$F$4:$F$75,"Japan") -> 6 | H42: =SUMIFS('Group Stage'!$I$4:$I$75,'Group Stage'!$E$4:$E$75,"Japan")+SUMIFS('Group Stage'!$H$4:$H$75,'Group Stage'!$F$4:$F$75,"Japan") -> 2 | I42: =G42-H42 -> 4 | J42: =3*D42+E42 -> 4
A43: =IF(SUM($C$41:$C$44)=0,"-",SUMPRODUCT(--(($J$41:$J$44*1000+$I$41:$I$44*10+$G$41:$G$44)>(J43*1000+I43*10+G43)))+1) -> 4 | B43: Tunisia | C43: =COUNTIFS('Group Stage'!$E$4:$E$75,"Tunisia",'Group Stage'!$H$4:$H$75,"<>")+COUNTIFS('Group Stage'!$F$4:$F$75,"Tunisia",'Group Stage'!$H$4:$H$75,"<>") -> 2 | D43: =SUMPRODUCT(('Group Stage'!$E$4:$E$75="Tunisia")*('Group Stage'!$H$4:$H$75<>"")*('Group Stage'!$H$4:$H$75>'Group Stage'!$I$4:$I$75))+SUMPRODUCT(('Group Stage'!$F$4:$F$75="Tunisia")*('Group Stage'!$H$4:$H$75<>"")*('Group Stage'!$I$4:$I$75>'Group Stage'!$H$4:$H$75)) -> 0 | E43: =SUMPRODUCT((('Group Stage'!$E$4:$E$75="Tunisia")+('Group Stage'!$F$4:$F$75="Tunisia"))*('Group Stage'!$H$4:$H$75<>"")*('Group Stage'!$H$4:$H$75='Group Stage'!$I$4:$I$75)) -> 0 | F43: =C43-D43-E43 -> 2 | G43: =SUMIFS('Group Stage'!$H$4:$H$75,'Group Stage'!$E$4:$E$75,"Tunisia")+SUMIFS('Group Stage'!$I$4:$I$75,'Group Stage'!$F$4:$F$75,"Tunisia") -> 1 | H43: =SUMIFS('Group Stage'!$I$4:$I$75,'Group Stage'!$E$4:$E$75,"Tunisia")+SUMIFS('Group Stage'!$H$4:$H$75,'Group Stage'!$F$4:$F$75,"Tunisia") -> 9 | I43: =G43-H43 -> -8 | J43: =3*D43+E43 -> 0
A44: =IF(SUM($C$41:$C$44)=0,"-",SUMPRODUCT(--(($J$41:$J$44*1000+$I$41:$I$44*10+$G$41:$G$44)>(J44*1000+I44*10+G44)))+1) -> 3 | B44: Sweden | C44: =COUNTIFS('Group Stage'!$E$4:$E$75,"Sweden",'Group Stage'!$H$4:$H$75,"<>")+COUNTIFS('Group Stage'!$F$4:$F$75,"Sweden",'Group Stage'!$H$4:$H$75,"<>") -> 2 | D44: =SUMPRODUCT(('Group Stage'!$E$4:$E$75="Sweden")*('Group Stage'!$H$4:$H$75<>"")*('Group Stage'!$H$4:$H$75>'Group Stage'!$I$4:$I$75))+SUMPRODUCT(('Group Stage'!$F$4:$F$75="Sweden")*('Group Stage'!$H$4:$H$75<>"")*('Group Stage'!$I$4:$I$75>'Group Stage'!$H$4:$H$75)) -> 1 | E44: =SUMPRODUCT((('Group Stage'!$E$4:$E$75="Sweden")+('Group Stage'!$F$4:$F$75="Sweden"))*('Group Stage'!$H$4:$H$75<>"")*('Group Stage'!$H$4:$H$75='Group Stage'!$I$4:$I$75)) -> 0 | F44: =C44-D44-E44 -> 1 | G44: =SUMIFS('Group Stage'!$H$4:$H$75,'Group Stage'!$E$4:$E$75,"Sweden")+SUMIFS('Group Stage'!$I$4:$I$75,'Group Stage'!$F$4:$F$75,"Sweden") -> 6 | H44: =SUMIFS('Group Stage'!$I$4:$I$75,'Group Stage'!$E$4:$E$75,"Sweden")+SUMIFS('Group Stage'!$H$4:$H$75,'Group Stage'!$F$4:$F$75,"Sweden") -> 6 | I44: =G44-H44 -> 0 | J44: =3*D44+E44 -> 3
A46: GROUP G
A47: Pos | B47: Team | C47: Pld | D47: W | E47: D | F47: L | G47: GF | H47: GA | I47: GD | J47: Pts
...

Sheet Group Stage
A1: GROUP STAGE — 72 matches in date order · predict every scoreline · 'J' = Joker (doubles points) · times in CT
A2: MATCH | H2: ACTUAL | J2: GANESH | N2: SIDDHESH | R2: ANIKET
A3: # | B3: Date | C3: KO (CT) | D3: Grp | E3: Home | F3: Away | G3: Lock | H3: Act H | I3: Act A | J3: G H | K3: G A | L3: Jk | M3: G Pts | N3: S H | O3: S A | P3: Jk | Q3: S Pts | R3: A H | S3: A A | T3: Jk | U3: A Pts | V3: Venue
A4: 1 | B4: Thu, Jun 11 | C4: 14:00 | D4: A | E4: Mexico | F4: South Africa | G4: L | H4: 2 | I4: 0 | J4: 2 | K4: 0 | M4: =IF(OR($H4="",$I4=""),"",IF(OR(J4="",K4=""),-1,(IF(AND(J4=$H4,K4=$I4),5,IF(SIGN(J4-K4)=SIGN($H4-$I4),IF((J4-K4)=($H4-$I4),4,3),0)))*IF(L4="J",2,1))) -> 5 | N4: 2 | O4: 1 | Q4: =IF(OR($H4="",$I4=""),"",IF(OR(N4="",O4=""),-1,(IF(AND(N4=$H4,O4=$I4),5,IF(SIGN(N4-O4)=SIGN($H4-$I4),IF((N4-O4)=($H4-$I4),4,3),0)))*IF(P4="J",2,1))) -> 3 | R4: 2 | S4: 0 | U4: =IF(OR($H4="",$I4=""),"",IF(OR(R4="",S4=""),-1,(IF(AND(R4=$H4,S4=$I4),5,IF(SIGN(R4-S4)=SIGN($H4-$I4),IF((R4-S4)=($H4-$I4),4,3),0)))*IF(T4="J",2,1))) -> 5 | V4: Estadio Azteca, Mexico City
A5: 2 | B5: Thu, Jun 11 | C5: 21:00 | D5: A | E5: South Korea | F5: Czechia | G5: L | H5: 2 | I5: 1 | J5: 1 | K5: 1 | M5: =IF(OR($H5="",$I5=""),"",IF(OR(J5="",K5=""),-1,(IF(AND(J5=$H5,K5=$I5),5,IF(SIGN(J5-K5)=SIGN($H5-$I5),IF((J5-K5)=($H5-$I5),4,3),0)))*IF(L5="J",2,1))) -> 0 | N5: 2 | O5: 1 | Q5: =IF(OR($H5="",$I5=""),"",IF(OR(N5="",O5=""),-1,(IF(AND(N5=$H5,O5=$I5),5,IF(SIGN(N5-O5)=SIGN($H5-$I5),IF((N5-O5)=($H5-$I5),4,3),0)))*IF(P5="J",2,1))) -> 5 | R5: 2 | S5: 1 | U5: =IF(OR($H5="",$I5=""),"",IF(OR(R5="",S5=""),-1,(IF(AND(R5=$H5,S5=$I5),5,IF(SIGN(R5-S5)=SIGN($H5-$I5),IF((R5-S5)=($H5-$I5),4,3),0)))*IF(T5="J",2,1))) -> 5 | V5: Estadio Akron, Guadalajara
A6: 3 | B6: Fri, Jun 12 | C6: 14:00 | D6: B | E6: Canada | F6: Bosnia-Herzegovina | G6: L | H6: 1 | I6: 1 | J6: 1 | K6: 0 | M6: =IF(OR($H6="",$I6=""),"",IF(OR(J6="",K6=""),-1,(IF(AND(J6=$H6,K6=$I6),5,IF(SIGN(J6-K6)=SIGN($H6-$I6),IF((J6-K6)=($H6-$I6),4,3),0)))*IF(L6="J",2,1))) -> 0 | N6: 1 | O6: 1 | Q6: =IF(OR($H6="",$I6=""),"",IF(OR(N6="",O6=""),-1,(IF(AND(N6=$H6,O6=$I6),5,IF(SIGN(N6-O6)=SIGN($H6-$I6),IF((N6-O6)=($H6-$I6),4,3),0)))*IF(P6="J",2,1))) -> 5 | R6: 2 | S6: 1 | U6: =IF(OR($H6="",$I6=""),"",IF(OR(R6="",S6=""),-1,(IF(AND(R6=$H6,S6=$I6),5,IF(SIGN(R6-S6)=SIGN($H6-$I6),IF((R6-S6)=($H6-$I6),4,3),0)))*IF(T6="J",2,1))) -> 0 | V6: BMO Field, Toronto
A7: 4 | B7: Fri, Jun 12 | C7: 20:00 | D7: D | E7: United States | F7: Paraguay | G7: L | H7: 4 | I7: 1 | J7: 2 | K7: 1 | M7: =IF(OR($H7="",$I7=""),"",IF(OR(J7="",K7=""),-1,(IF(AND(J7=$H7,K7=$I7),5,IF(SIGN(J7-K7)=SIGN($H7-$I7),IF((J7-K7)=($H7-$I7),4,3),0)))*IF(L7="J",2,1))) -> 3 | N7: 3 | O7: 2 | Q7: =IF(OR($H7="",$I7=""),"",IF(OR(N7="",O7=""),-1,(IF(AND(N7=$H7,O7=$I7),5,IF(SIGN(N7-O7)=SIGN($H7-$I7),IF((N7-O7)=($H7-$I7),4,3),0)))*IF(P7="J",2,1))) -> 3 | R7: 1 | S7: 0 | U7: =IF(OR($H7="",$I7=""),"",IF(OR(R7="",S7=""),-1,(IF(AND(R7=$H7,S7=$I7),5,IF(SIGN(R7-S7)=SIGN($H7-$I7),IF((R7-S7)=($H7-$I7),4,3),0)))*IF(T7="J",2,1))) -> 3 | V7: SoFi Stadium, Inglewood
A8: 5 | B8: Fri, Jun 12 | C8: 23:00 | D8: D | E8: Australia | F8: Türkiye | G8: L | H8: 2 | I8: 0 | J8: 1 | K8: 2 | M8: =IF(OR($H8="",$I8=""),"",IF(OR(J8="",K8=""),-1,(IF(AND(J8=$H8,K8=$I8),5,IF(SIGN(J8-K8)=SIGN($H8-$I8),IF((J8-K8)=($H8-$I8),4,3),0)))*IF(L8="J",2,1))) -> 0 | N8: 1 | O8: 2 | Q8: =IF(OR($H8="",$I8=""),"",IF(OR(N8="",O8=""),-1,(IF(AND(N8=$H8,O8=$I8),5,IF(SIGN(N8-O8)=SIGN($H8-$I8),IF((N8-O8)=($H8-$I8),4,3),0)))*IF(P8="J",2,1))) -> 0 | R8: 0 | S8: 1 | U8: =IF(OR($H8="",$I8=""),"",IF(OR(R8="",S8=""),-1,(IF(AND(R8=$H8,S8=$I8),5,IF(SIGN(R8-S8)=SIGN($H8-$I8),IF((R8-S8)=($H8-$I8),4,3),0)))*IF(T8="J",2,1))) -> 0 | V8: BC Place, Vancouver
A9: 6 | B9: Sat, Jun 13 | C9: 13:00 | D9: B | E9: Qatar | F9: Switzerland | G9: L | H9: 1 | I9: 1 | J9: 0 | K9: 2 | M9: =IF(OR($H9="",$I9=""),"",IF(OR(J9="",K9=""),-1,(IF(AND(J9=$H9,K9=$I9),5,IF(SIGN(J9-K9)=SIGN($H9-$I9),IF((J9-K9)=($H9-$I9),4,3),0)))*IF(L9="J",2,1))) -> 0 | N9: 0 | O9: 2 | Q9: =IF(OR($H9="",$I9=""),"",IF(OR(N9="",O9=""),-1,(IF(AND(N9=$H9,O9=$I9),5,IF(SIGN(N9-O9)=SIGN($H9-$I9),IF((N9-O9)=($H9-$I9),4,3),0)))*IF(P9="J",2,1))) -> 0 | R9: 0 | S9: 2 | U9: =IF(OR($H9="",$I9=""),"",IF(OR(R9="",S9=""),-1,(IF(AND(R9=$H9,S9=$I9),5,IF(SIGN(R9-S9)=SIGN($H9-$I9),IF((R9-S9)=($H9-$I9),4,3),0)))*IF(T9="J",2,1))) -> 0 | V9: Levi's Stadium, Santa Clara
A10: 7 | B10: Sat, Jun 13 | C10: 16:00 | D10: C | E10: Brazil | F10: Morocco | G10: L | H10: 1 | I10: 1 | J10: 1 | K10: 2 | M10: =IF(OR($H10="",$I10=""),"",IF(OR(J10="",K10=""),-1,(IF(AND(J10=$H10,K10=$I10),5,IF(SIGN(J10-K10)=SIGN($H10-$I10),IF((J10-K10)=($H10-$I10),4,3),0)))*IF(L10="J",2,1))) -> 0 | N10: 2 | O10: 2 | Q10: =IF(OR($H10="",$I10=""),"",IF(OR(N10="",O10=""),-1,(IF(AND(N10=$H10,O10=$I10),5,IF(SIGN(N10-O10)=SIGN($H10-$I10),IF((N10-O10)=($H10-$I10),4,3),0)))*IF(P10="J",2,1))) -> 4 | R10: 2 | S10: 1 | U10: =IF(OR($H10="",$I10=""),"",IF(OR(R10="",S10=""),-1,(IF(AND(R10=$H10,S10=$I10),5,IF(SIGN(R10-S10)=SIGN($H10-$I10),IF((R10-S10)=($H10-$I10),4,3),0)))*IF(T10="J",2,1))) -> 0 | V10: MetLife Stadium, East Rutherford
A11: 8 | B11: Sat, Jun 13 | C11: 20:00 | D11: C | E11: Haiti | F11: Scotland | G11: L | H11: 0 | I11: 1 | J11: 0 | K11: 2 | M11: =IF(OR($H11="",$I11=""),"",IF(OR(J11="",K11=""),-1,(IF(AND(J11=$H11,K11=$I11),5,IF(SIGN(J11-K11)=SIGN($H11-$I11),IF((J11-K11)=($H11-$I11),4,3),0)))*IF(L11="J",2,1))) -> 3 | N11: 0 | O11: 2 | Q11: =IF(OR($H11="",$I11=""),"",IF(OR(N11="",O11=""),-1,(IF(AND(N11=$H11,O11=$I11),5,IF(SIGN(N11-O11)=SIGN($H11-$I11),IF((N11-O11)=($H11-$I11),4,3),0)))*IF(P11="J",2,1))) -> 3 | R11: 0 | S11: 2 | U11: =IF(OR($H11="",$I11=""),"",IF(OR(R11="",S11=""),-1,(IF(AND(R11=$H11,S11=$I11),5,IF(SIGN(R11-S11)=SIGN($H11-$I11),IF((R11-S11)=($H11-$I11),4,3),0)))*IF(T11="J",2,1))) -> 3 | V11: Gillette Stadium, Foxboro
A12: 9 | B12: Sun, Jun 14 | C12: 12:00 | D12: E | E12: Germany | F12: Curaçao | G12: L | H12: 7 | I12: 1 | J12: 3 | K12: 0 | L12: J | M12: =IF(OR($H12="",$I12=""),"",IF(OR(J12="",K12=""),-1,(IF(AND(J12=$H12,K12=$I12),5,IF(SIGN(J12-K12)=SIGN($H12-$I12),IF((J12-K12)=($H12-$I12),4,3),0)))*IF(L12="J",2,1))) -> 6 | N12: 4 | O12: 0 | P12: J | Q12: =IF(OR($H12="",$I12=""),"",IF(OR(N12="",O12=""),-1,(IF(AND(N12=$H12,O12=$I12),5,IF(SIGN(N12-O12)=SIGN($H12-$I12),IF((N12-O12)=($H12-$I12),4,3),0)))*IF(P12="J",2,1))) -> 6 | R12: 4 | S12: 0 | T12: J | U12: =IF(OR($H12="",$I12=""),"",IF(OR(R12="",S12=""),-1,(IF(AND(R12=$H12,S12=$I12),5,IF(SIGN(R12-S12)=SIGN($H12-$I12),IF((R12-S12)=($H12-$I12),4,3),0)))*IF(T12="J",2,1))) -> 6 | V12: NRG Stadium, Houston
A13: 10 | B13: Sun, Jun 14 | C13: 15:00 | D13: F | E13: Netherlands | F13: Japan | G13: L | H13: 2 | I13: 2 | J13: 2 | K13: 1 | M13: =IF(OR($H13="",$I13=""),"",IF(OR(J13="",K13=""),-1,(IF(AND(J13=$H13,K13=$I13),5,IF(SIGN(J13-K13)=SIGN($H13-$I13),IF((J13-K13)=($H13-$I13),4,3),0)))*IF(L13="J",2,1))) -> 0 | N13: 0 | O13: 0 | Q13: =IF(OR($H13="",$I13=""),"",IF(OR(N13="",O13=""),-1,(IF(AND(N13=$H13,O13=$I13),5,IF(SIGN(N13-O13)=SIGN($H13-$I13),IF((N13-O13)=($H13-$I13),4,3),0)))*IF(P13="J",2,1))) -> 4 | R13: 1 | S13: 1 | U13: =IF(OR($H13="",$I13=""),"",IF(OR(R13="",S13=""),-1,(IF(AND(R13=$H13,S13=$I13),5,IF(SIGN(R13-S13)=SIGN($H13-$I13),IF((R13-S13)=($H13-$I13),4,3),0)))*IF(T13="J",2,1))) -> 4 | V13: AT&T Stadium, Arlington
A14: 11 | B14: Sun, Jun 14 | C14: 18:00 | D14: E | E14: Ivory Coast | F14: Ecuador | G14: L | H14: 1 | I14: 0 | J14: 1 | K14: 1 | M14: =IF(OR($H14="",$I14=""),"",IF(OR(J14="",K14=""),-1,(IF(AND(J14=$H14,K14=$I14),5,IF(SIGN(J14-K14)=SIGN($H14-$I14),IF((J14-K14)=($H14-$I14),4,3),0)))*IF(L14="J",2,1))) -> 0 | N14: 1 | O14: 1 | Q14: 0 | R14: 1 | S14: 1 | U14: =IF(OR($H14="",$I14=""),"",IF(OR(R14="",S14=""),-1,(IF(AND(R14=$H14,S14=$I14),5,IF(SIGN(R14-S14)=SIGN($H14-$I14),IF((R14-S14)=($H14-$I14),4,3),0)))*IF(T14="J",2,1))) -> 0 | V14: Lincoln Financial Field, Philadelphia
A15: 12 | B15: Sun, Jun 14 | C15: 21:00 | D15: F | E15: Sweden | F15: Tunisia | G15: L | H15: 5 | I15: 1 | J15: 1 | K15: 0 | M15: =IF(OR($H15="",$I15=""),"",IF(OR(J15="",K15=""),-1,(IF(AND(J15=$H15,K15=$I15),5,IF(SIGN(J15-K15)=SIGN($H15-$I15),IF((J15-K15)=($H15-$I15),4,3),0)))*IF(L15="J",2,1))) -> 3 | N15: 1 | O15: 0 | Q15: =IF(OR($H15="",$I15=""),"",IF(OR(N15="",O15=""),-1,(IF(AND(N15=$H15,O15=$I15),5,IF(SIGN(N15-O15)=SIGN($H15-$I15),IF((N15-O15)=($H15-$I15),4,3),0)))*IF(P15="J",2,1))) -> 3 | R15: 1 | S15: 0 | U15: =IF(OR($H15="",$I15=""),"",IF(OR(R15="",S15=""),-1,(IF(AND(R15=$H15,S15=$I15),5,IF(SIGN(R15-S15)=SIGN($H15-$I15),IF((R15-S15)=($H15-$I15),4,3),0)))*IF(T15="J",2,1))) -> 3 | V15: Estadio BBVA, Monterrey
A16: 13 | B16: Mon, Jun 15 | C16: 11:00 | D16: H | E16: Spain | F16: Cape Verde | G16: L | H16: 0 | I16: 0 | J16: 5 | K16: 0 | M16: =IF(OR($H16="",$I16=""),"",IF(OR(J16="",K16=""),-1,(IF(AND(J16=$H16,K16=$I16),5,IF(SIGN(J16-K16)=SIGN($H16-$I16),IF((J16-K16)=($H16-$I16),4,3),0)))*IF(L16="J",2,1))) -> 0 | N16: 4 | O16: 0 | P16: J | Q16: =IF(OR($H16="",$I16=""),"",IF(OR(N16="",O16=""),-1,(IF(AND(N16=$H16,O16=$I16),5,IF(SIGN(N16-O16)=SIGN($H16-$I16),IF((N16-O16)=($H16-$I16),4,3),0)))*IF(P16="J",2,1))) -> 0 | R16: 4 | S16: 0 | T16: J | U16: =IF(OR($H16="",$I16=""),"",IF(OR(R16="",S16=""),-1,(IF(AND(R16=$H16,S16=$I16),5,IF(SIGN(R16-S16)=SIGN($H16-$I16),IF((R16-S16)=($H16-$I16),4,3),0)))*IF(T16="J",2,1))) -> 0 | V16: Mercedes-Benz Stadium, Atlanta
A17: 14 | B17: Mon, Jun 15 | C17: 14:00 | D17: G | E17: Belgium | F17: Egypt | G17: L | H17: 1 | I17: 1 | J17: 2 | K17: 1 | M17: =IF(OR($H17="",$I17=""),"",IF(OR(J17="",K17=""),-1,(IF(AND(J17=$H17,K17=$I17),5,IF(SIGN(J17-K17)=SIGN($H17-$I17),IF((J17-K17)=($H17-$I17),4,3),0)))*IF(L17="J",2,1))) -> 0 | N17: 1 | O17: 1 | Q17: =IF(OR($H17="",$I17=""),"",IF(OR(N17="",O17=""),-1,(IF(AND(N17=$H17,O17=$I17),5,IF(SIGN(N17-O17)=SIGN($H17-$I17),IF((N17-O17)=($H17-$I17),4,3),0)))*IF(P17="J",2,1))) -> 5 | R17: 2 | S17: 1 | U17: =IF(OR($H17="",$I17=""),"",IF(OR(R17="",S17=""),-1,(IF(AND(R17=$H17,S17=$I17),5,IF(SIGN(R17-S17)=SIGN($H17-$I17),IF((R17-S17)=($H17-$I17),4,3),0)))*IF(T17="J",2,1))) -> 0 | V17: Lumen Field, Seattle
A18: 15 | B18: Mon, Jun 15 | C18: 17:00 | D18: H | E18: Saudi Arabia | F18: Uruguay | G18: L | H18: 1 | I18: 1 | J18: 1 | K18: 2 | M18: =IF(OR($H18="",$I18=""),"",IF(OR(J18="",K18=""),-1,(IF(AND(J18=$H18,K18=$I18),5,IF(SIGN(J18-K18)=SIGN($H18-$I18),IF((J18-K18)=($H18-$I18),4,3),0)))*IF(L18="J",2,1))) -> 0 | N18: 0 | O18: 1 | Q18: =IF(OR($H18="",$I18=""),"",IF(OR(N18="",O18=""),-1,(IF(AND(N18=$H18,O18=$I18),5,IF(SIGN(N18-O18)=SIGN($H18-$I18),IF((N18-O18)=($H18-$I18),4,3),0)))*IF(P18="J",2,1))) -> 0 | R18: 0 | S18: 1 | U18: =IF(OR($H18="",$I18=""),"",IF(OR(R18="",S18=""),-1,(IF(AND(R18=$H18,S18=$I18),5,IF(SIGN(R18-S18)=SIGN($H18-$I18),IF((R18-S18)=($H18-$I18),4,3),0)))*IF(T18="J",2,1))) -> 0 | V18: Hard Rock Stadium, Miami
A19: 16 | B19: Mon, Jun 15 | C19: 20:00 | D19: G | E19: Iran | F19: New Zealand | G19: L | H19: 2 | I19: 2 | J19: 1 | K19: 0 | M19: =IF(OR($H19="",$I19=""),"",IF(OR(J19="",K19=""),-1,(IF(AND(J19=$H19,K19=$I19),5,IF(SIGN(J19-K19)=SIGN($H19-$I19),IF((J19-K19)=($H19-$I19),4,3),0)))*IF(L19="J",2,1))) -> 0 | N19: 1 | O19: 1 | Q19: =IF(OR($H19="",$I19=""),"",IF(OR(N19="",O19=""),-1,(IF(AND(N19=$H19,O19=$I19),5,IF(SIGN(N19-O19)=SIGN($H19-$I19),IF((N19-O19)=($H19-$I19),4,3),0)))*IF(P19="J",2,1))) -> 4 | R19: 1 | S19: 0 | U19: =IF(OR($H19="",$I19=""),"",IF(OR(R19="",S19=""),-1,(IF(AND(R19=$H19,S19=$I19),5,IF(SIGN(R19-S19)=SIGN($H19-$I19),IF((R19-S19)=($H19-$I19),4,3),0)))*IF(T19="J",2,1))) -> 0 | V19: SoFi Stadium, Inglewood
A20: 18 | B20: Tue, Jun 16 | C20: 14:00 | D20: I | E20: France | F20: Senegal | G20: L | H20: 3 | I20: 1 | J20: 3 | K20: 1 | M20: =IF(OR($H20="",$I20=""),"",IF(OR(J20="",K20=""),-1,(IF(AND(J20=$H20,K20=$I20),5,IF(SIGN(J20-K20)=SIGN($H20-$I20),IF((J20-K20)=($H20-$I20),4,3),0)))*IF(L20="J",2,1))) -> 5 | N20: 2 | O20: 1 | Q20: =IF(OR($H20="",$I20=""),"",IF(OR(N20="",O20=""),-1,(IF(AND(N20=$H20,O20=$I20),5,IF(SIGN(N20-O20)=SIGN($H20-$I20),IF((N20-O20)=($H20-$I20),4,3),0)))*IF(P20="J",2,1))) -> 3 | R20: 2 | S20: 1 | U20: =IF(OR($H20="",$I20=""),"",IF(OR(R20="",S20=""),-1,(IF(AND(R20=$H20,S20=$I20),5,IF(SIGN(R20-S20)=SIGN($H20-$I20),IF((R20-S20)=($H20-$I20),4,3),0)))*IF(T20="J",2,1))) -> 3 | V20: MetLife Stadium, East Rutherford
A21: 19 | B21: Tue, Jun 16 | C21: 17:00 | D21: I | E21: Iraq | F21: Norway | G21: L | H21: 1 | I21: 4 | J21: 0 | K21: 3 | L21: J | M21: =IF(OR($H21="",$I21=""),"",IF(OR(J21="",K21=""),-1,(IF(AND(J21=$H21,K21=$I21),5,IF(SIGN(J21-K21)=SIGN($H21-$I21),IF((J21-K21)=($H21-$I21),4,3),0)))*IF(L21="J",2,1))) -> 8 | N21: 0 | O21: 3 | Q21: =IF(OR($H21="",$I21=""),"",IF(OR(N21="",O21=""),-1,(IF(AND(N21=$H21,O21=$I21),5,IF(SIGN(N21-O21)=SIGN($H21-$I21),IF((N21-O21)=($H21-$I21),4,3),0)))*IF(P21="J",2,1))) -> 4 | R21: 0 | S21: 2 | U21: =IF(OR($H21="",$I21=""),"",IF(OR(R21="",S21=""),-1,(IF(AND(R21=$H21,S21=$I21),5,IF(SIGN(R21-S21)=SIGN($H21-$I21),IF((R21-S21)=($H21-$I21),4,3),0)))*IF(T21="J",2,1))) -> 3 | V21: Gillette Stadium, Foxborough
A22: 20 | B22: Tue, Jun 16 | C22: 20:00 | D22: J | E22: Argentina | F22: Algeria | G22: L | H22: 3 | I22: 0 | J22: 2 | K22: 1 | M22: =IF(OR($H22="",$I22=""),"",IF(OR(J22="",K22=""),-1,(IF(AND(J22=$H22,K22=$I22),5,IF(SIGN(J22-K22)=SIGN($H22-$I22),IF((J22-K22)=($H22-$I22),4,3),0)))*IF(L22="J",2,1))) -> 3 | N22: 2 | O22: 1 | Q22: =IF(OR($H22="",$I22=""),"",IF(OR(N22="",O22=""),-1,(IF(AND(N22=$H22,O22=$I22),5,IF(SIGN(N22-O22)=SIGN($H22-$I22),IF((N22-O22)=($H22-$I22),4,3),0)))*IF(P22="J",2,1))) -> 3 | R22: 3 | S22: 1 | U22: =IF(OR($H22="",$I22=""),"",IF(OR(R22="",S22=""),-1,(IF(AND(R22=$H22,S22=$I22),5,IF(SIGN(R22-S22)=SIGN($H22-$I22),IF((R22-S22)=($H22-$I22),4,3),0)))*IF(T22="J",2,1))) -> 3 | V22: Arrowhead Stadium, Kansas City
A23: 17 | B23: Tue, Jun 16 | C23: 23:00 | D23: J | E23: Austria | F23: Jordan | G23: L | H23: 3 | I23: 1 | J23: 2 | K23: 0 | M23: =IF(OR($H23="",$I23=""),"",IF(OR(J23="",K23=""),-1,(IF(AND(J23=$H23,K23=$I23),5,IF(SIGN(J23-K23)=SIGN($H23-$I23),IF((J23-K23)=($H23-$I23),4,3),0)))*IF(L23="J",2,1))) -> 4 | N23: 1 | O23: 0 | Q23: =IF(OR($H23="",$I23=""),"",IF(OR(N23="",O23=""),-1,(IF(AND(N23=$H23,O23=$I23),5,IF(SIGN(N23-O23)=SIGN($H23-$I23),IF((N23-O23)=($H23-$I23),4,3),0)))*IF(P23="J",2,1))) -> 3 | R23: 2 | S23: 0 | U23: =IF(OR($H23="",$I23=""),"",IF(OR(R23="",S23=""),-1,(IF(AND(R23=$H23,S23=$I23),5,IF(SIGN(R23-S23)=SIGN($H23-$I23),IF((R23-S23)=($H23-$I23),4,3),0)))*IF(T23="J",2,1))) -> 4 | V23: Levi's Stadium, Santa Clara
A24: 21 | B24: Wed, Jun 17 | C24: 12:00 | D24: K | E24: Portugal | F24: DR Congo | G24: L | H24: 1 | I24: 1 | J24: 3 | K24: 0 | M24: =IF(OR($H24="",$I24=""),"",IF(OR(J24="",K24=""),-1,(IF(AND(J24=$H24,K24=$I24),5,IF(SIGN(J24-K24)=SIGN($H24-$I24),IF((J24-K24)=($H24-$I24),4,3),0)))*IF(L24="J",2,1))) -> 0 | N24: 5 | O24: 0 | P24: J | Q24: =IF(OR($H24="",$I24=""),"",IF(OR(N24="",O24=""),-1,(IF(AND(N24=$H24,O24=$I24),5,IF(SIGN(N24-O24)=SIGN($H24-$I24),IF((N24-O24)=($H24-$I24),4,3),0)))*IF(P24="J",2,1))) -> 0 | R24: 3 | S24: 0 | U24: =IF(OR($H24="",$I24=""),"",IF(OR(R24="",S24=""),-1,(IF(AND(R24=$H24,S24=$I24),5,IF(SIGN(R24-S24)=SIGN($H24-$I24),IF((R24-S24)=($H24-$I24),4,3),0)))*IF(T24="J",2,1))) -> 0 | V24: NRG Stadium, Houston
A25: 22 | B25: Wed, Jun 17 | C25: 15:00 | D25: L | E25: England | F25: Croatia | G25: L | H25: 4 | I25: 2 | J25: 3 | K25: 1 | M25: =IF(OR($H25="",$I25=""),"",IF(OR(J25="",K25=""),-1,(IF(AND(J25=$H25,K25=$I25),5,IF(SIGN(J25-K25)=SIGN($H25-$I25),IF((J25-K25)=($H25-$I25),4,3),0)))*IF(L25="J",2,1))) -> 4 | N25: 2 | O25: 1 | Q25: =IF(OR($H25="",$I25=""),"",IF(OR(N25="",O25=""),-1,(IF(AND(N25=$H25,O25=$I25),5,IF(SIGN(N25-O25)=SIGN($H25-$I25),IF((N25-O25)=($H25-$I25),4,3),0)))*IF(P25="J",2,1))) -> 3 | R25: 1 | S25: 1 | U25: =IF(OR($H25="",$I25=""),"",IF(OR(R25="",S25=""),-1,(IF(AND(R25=$H25,S25=$I25),5,IF(SIGN(R25-S25)=SIGN($H25-$I25),IF((R25-S25)=($H25-$I25),4,3),0)))*IF(T25="J",2,1))) -> 0 | V25: AT&T Stadium, Arlington
A26: 23 | B26: Wed, Jun 17 | C26: 18:00 | D26: L | E26: Ghana | F26: Panama | G26: L | H26: 1 | I26: 0 | J26: 1 | K26: 0 | M26: =IF(OR($H26="",$I26=""),"",IF(OR(J26="",K26=""),-1,(IF(AND(J26=$H26,K26=$I26),5,IF(SIGN(J26-K26)=SIGN($H26-$I26),IF((J26-K26)=($H26-$I26),4,3),0)))*IF(L26="J",2,1))) -> 5 | N26: 3 | O26: 1 | Q26: =IF(OR($H26="",$I26=""),"",IF(OR(N26="",O26=""),-1,(IF(AND(N26=$H26,O26=$I26),5,IF(SIGN(N26-O26)=SIGN($H26-$I26),IF((N26-O26)=($H26-$I26),4,3),0)))*IF(P26="J",2,1))) -> 3 | R26: 2 | S26: 1 | U26: =IF(OR($H26="",$I26=""),"",IF(OR(R26="",S26=""),-1,(IF(AND(R26=$H26,S26=$I26),5,IF(SIGN(R26-S26)=SIGN($H26-$I26),IF((R26-S26)=($H26-$I26),4,3),0)))*IF(T26="J",2,1))) -> 4 | V26: BMO Field, Toronto
A27: 24 | B27: Wed, Jun 17 | C27: 21:00 | D27: K | E27: Uzbekistan | F27: Colombia | G27: L | H27: 1 | I27: 3 | J27: 0 | K27: 2 | M27: =IF(OR($H27="",$I27=""),"",IF(OR(J27="",K27=""),-1,(IF(AND(J27=$H27,K27=$I27),5,IF(SIGN(J27-K27)=SIGN($H27-$I27),IF((J27-K27)=($H27-$I27),4,3),0)))*IF(L27="J",2,1))) -> 4 | N27: 1 | O27: 3 | Q27: =IF(OR($H27="",$I27=""),"",IF(OR(N27="",O27=""),-1,(IF(AND(N27=$H27,O27=$I27),5,IF(SIGN(N27-O27)=SIGN($H27-$I27),IF((N27-O27)=($H27-$I27),4,3),0)))*IF(P27="J",2,1))) -> 5 | R27: 0 | S27: 2 | U27: =IF(OR($H27="",$I27=""),"",IF(OR(R27="",S27=""),-1,(IF(AND(R27=$H27,S27=$I27),5,IF(SIGN(R27-S27)=SIGN($H27-$I27),IF((R27-S27)=($H27-$I27),4,3),0)))*IF(T27="J",2,1))) -> 4 | V27: Estadio Azteca, Mexico City
A28: 25 | B28: Thu, Jun 18 | C28: 11:00 | D28: A | E28: Czechia | F28: South Africa | G28: L | H28: 1 | I28: 1 | J28: 2 | K28: 1 | M28: =IF(OR($H28="",$I28=""),"",IF(OR(J28="",K28=""),-1,(IF(AND(J28=$H28,K28=$I28),5,IF(SIGN(J28-K28)=SIGN($H28-$I28),IF((J28-K28)=($H28-$I28),4,3),0)))*IF(L28="J",2,1))) -> 0 | N28: 2 | O28: 1 | Q28: =IF(OR($H28="",$I28=""),"",IF(OR(N28="",O28=""),-1,(IF(AND(N28=$H28,O28=$I28),5,IF(SIGN(N28-O28)=SIGN($H28-$I28),IF((N28-O28)=($H28-$I28),4,3),0)))*IF(P28="J",2,1))) -> 0 | R28: 1 | S28: 0 | U28: =IF(OR($H28="",$I28=""),"",IF(OR(R28="",S28=""),-1,(IF(AND(R28=$H28,S28=$I28),5,IF(SIGN(R28-S28)=SIGN($H28-$I28),IF((R28-S28)=($H28-$I28),4,3),0)))*IF(T28="J",2,1))) -> 0 | V28: Mercedes-Benz Stadium, Atlanta
A29: 26 | B29: Thu, Jun 18 | C29: 14:00 | D29: B | E29: Switzerland | F29: Bosnia-Herzegovina | G29: L | H29: 4 | I29: 1 | J29: 2 | K29: 1 | M29: =IF(OR($H29="",$I29=""),"",IF(OR(J29="",K29=""),-1,(IF(AND(J29=$H29,K29=$I29),5,IF(SIGN(J29-K29)=SIGN($H29-$I29),IF((J29-K29)=($H29-$I29),4,3),0)))*IF(L29="J",2,1))) -> 3 | N29: 1 | O29: 1 | Q29: =IF(OR($H29="",$I29=""),"",IF(OR(N29="",O29=""),-1,(IF(AND(N29=$H29,O29=$I29),5,IF(SIGN(N29-O29)=SIGN($H29-$I29),IF((N29-O29)=($H29-$I29),4,3),0)))*IF(P29="J",2,1))) -> 0 | R29: 2 | S29: 1 | U29: =IF(OR($H29="",$I29=""),"",IF(OR(R29="",S29=""),-1,(IF(AND(R29=$H29,S29=$I29),5,IF(SIGN(R29-S29)=SIGN($H29-$I29),IF((R29-S29)=($H29-$I29),4,3),0)))*IF(T29="J",2,1))) -> 3 | V29: SoFi Stadium, Inglewood
A30: 27 | B30: Thu, Jun 18 | C30: 17:00 | D30: B | E30: Canada | F30: Qatar | G30: L | H30: 6 | I30: 0 | J30: 1 | K30: 1 | M30: =IF(OR($H30="",$I30=""),"",IF(OR(J30="",K30=""),-1,(IF(AND(J30=$H30,K30=$I30),5,IF(SIGN(J30-K30)=SIGN($H30-$I30),IF((J30-K30)=($H30-$I30),4,3),0)))*IF(L30="J",2,1))) -> 0 | N30: 2 | O30: 0 | Q30: =IF(OR($H30="",$I30=""),"",IF(OR(N30="",O30=""),-1,(IF(AND(N30=$H30,O30=$I30),5,IF(SIGN(N30-O30)=SIGN($H30-$I30),IF((N30-O30)=($H30-$I30),4,3),0)))*IF(P30="J",2,1))) -> 3 | R30: 2 | S30: 1 | U30: =IF(OR($H30="",$I30=""),"",IF(OR(R30="",S30=""),-1,(IF(AND(R30=$H30,S30=$I30),5,IF(SIGN(R30-S30)=SIGN($H30-$I30),IF((R30-S30)=($H30-$I30),4,3),0)))*IF(T30="J",2,1))) -> 3 | V30: BC Place, Vancouver
A31: 28 | B31: Thu, Jun 18 | C31: 20:00 | D31: A | E31: Mexico | F31: South Korea | G31: L | H31: 1 | I31: 0 | J31: 2 | K31: 1 | M31: =IF(OR($H31="",$I31=""),"",IF(OR(J31="",K31=""),-1,(IF(AND(J31=$H31,K31=$I31),5,IF(SIGN(J31-K31)=SIGN($H31-$I31),IF((J31-K31)=($H31-$I31),4,3),0)))*IF(L31="J",2,1))) -> 4 | N31: 2 | O31: 2 | Q31: =IF(OR($H31="",$I31=""),"",IF(OR(N31="",O31=""),-1,(IF(AND(N31=$H31,O31=$I31),5,IF(SIGN(N31-O31)=SIGN($H31-$I31),IF((N31-O31)=($H31-$I31),4,3),0)))*IF(P31="J",2,1))) -> 0 | R31: 2 | S31: 2 | U31: =IF(OR($H31="",$I31=""),"",IF(OR(R31="",S31=""),-1,(IF(AND(R31=$H31,S31=$I31),5,IF(SIGN(R31-S31)=SIGN($H31-$I31),IF((R31-S31)=($H31-$I31),4,3),0)))*IF(T31="J",2,1))) -> 0 | V31: Estadio Akron, Guadalajara
A32: 29 | B32: Fri, Jun 19 | C32: 14:00 | D32: D | E32: United States | F32: Australia | G32: L | H32: 2 | I32: 0 | J32: 2 | K32: 1 | M32: =IF(OR($H32="",$I32=""),"",IF(OR(J32="",K32=""),-1,(IF(AND(J32=$H32,K32=$I32),5,IF(SIGN(J32-K32)=SIGN($H32-$I32),IF((J32-K32)=($H32-$I32),4,3),0)))*IF(L32="J",2,1))) -> 3 | N32: 2 | O32: 1 | Q32: =IF(OR($H32="",$I32=""),"",IF(OR(N32="",O32=""),-1,(IF(AND(N32=$H32,O32=$I32),5,IF(SIGN(N32-O32)=SIGN($H32-$I32),IF((N32-O32)=($H32-$I32),4,3),0)))*IF(P32="J",2,1))) -> 3 | R32: 2 | S32: 1 | U32: =IF(OR($H32="",$I32=""),"",IF(OR(R32="",S32=""),-1,(IF(AND(R32=$H32,S32=$I32),5,IF(SIGN(R32-S32)=SIGN($H32-$I32),IF((R32-S32)=($H32-$I32),4,3),0)))*IF(T32="J",2,1))) -> 3 | V32: Lumen Field, Seattle
A33: 30 | B33: Fri, Jun 19 | C33: 17:00 | D33: C | E33: Scotland | F33: Morocco | G33: L | H33: 0 | I33: 1 | J33: 1 | K33: 2 | M33: =IF(OR($H33="",$I33=""),"",IF(OR(J33="",K33=""),-1,(IF(AND(J33=$H33,K33=$I33),5,IF(SIGN(J33-K33)=SIGN($H33-$I33),IF((J33-K33)=($H33-$I33),4,3),0)))*IF(L33="J",2,1))) -> 4 | N33: 1 | O33: 2 | Q33: =IF(OR($H33="",$I33=""),"",IF(OR(N33="",O33=""),-1,(IF(AND(N33=$H33,O33=$I33),5,IF(SIGN(N33-O33)=SIGN($H33-$I33),IF((N33-O33)=($H33-$I33),4,3),0)))*IF(P33="J",2,1))) -> 4 | R33: 1 | S33: 2 | U33: =IF(OR($H33="",$I33=""),"",IF(OR(R33="",S33=""),-1,(IF(AND(R33=$H33,S33=$I33),5,IF(SIGN(R33-S33)=SIGN($H33-$I33),IF((R33-S33)=($H33-$I33),4,3),0)))*IF(T33="J",2,1))) -> 4 | V33: Gillette Stadium, Foxboro
A34: 31 | B34: Fri, Jun 19 | C34: 19:30 | D34: C | E34: Brazil | F34: Haiti | G34: L | H34: 3 | I34: 0 | J34: 3 | K34: 0 | L34: J | M34: =IF(OR($H34="",$I34=""),"",IF(OR(J34="",K34=""),-1,(IF(AND(J34=$H34,K34=$I34),5,IF(SIGN(J34-K34)=SIGN($H34-$I34),IF((J34-K34)=($H34-$I34),4,3),0)))*IF(L34="J",2,1))) -> 10 | N34: 3 | O34: 0 | P34: J | Q34: =IF(OR($H34="",$I34=""),"",IF(OR(N34="",O34=""),-1,(IF(AND(N34=$H34,O34=$I34),5,IF(SIGN(N34-O34)=SIGN($H34-$I34),IF((N34-O34)=($H34-$I34),4,3),0)))*IF(P34="J",2,1))) -> 10 | R34: 3 | S34: 0 | U34: =IF(OR($H34="",$I34=""),"",IF(OR(R34="",S34=""),-1,(IF(AND(R34=$H34,S34=$I34),5,IF(SIGN(R34-S34)=SIGN($H34-$I34),IF((R34-S34)=($H34-$I34),4,3),0)))*IF(T34="J",2,1))) -> 5 | V34: Lincoln Financial Field, Philadelphia
A35: 32 | B35: Fri, Jun 19 | C35: 22:00 | D35: D | E35: Türkiye | F35: Paraguay | G35: L | H35: 0 | I35: 1 | J35: 2 | K35: 1 | M35: =IF(OR($H35="",$I35=""),"",IF(OR(J35="",K35=""),-1,(IF(AND(J35=$H35,K35=$I35),5,IF(SIGN(J35-K35)=SIGN($H35-$I35),IF((J35-K35)=($H35-$I35),4,3),0)))*IF(L35="J",2,1))) -> 0 | N35: 2 | O35: 1 | Q35: =IF(OR($H35="",$I35=""),"",IF(OR(N35="",O35=""),-1,(IF(AND(N35=$H35,O35=$I35),5,IF(SIGN(N35-O35)=SIGN($H35-$I35),IF((N35-O35)=($H35-$I35),4,3),0)))*IF(P35="J",2,1))) -> 0 | R35: 1 | S35: 0 | U35: =IF(OR($H35="",$I35=""),"",IF(OR(R35="",S35=""),-1,(IF(AND(R35=$H35,S35=$I35),5,IF(SIGN(R35-S35)=SIGN($H35-$I35),IF((R35-S35)=($H35-$I35),4,3),0)))*IF(T35="J",2,1))) -> 0 | V35: Levi's Stadium, Santa Clara
A36: 33 | B36: Fri, Jun 19 | C36: 23:00 | D36: F | E36: Tunisia | F36: Japan | G36: L | H36: 0 | I36: 4 | J36: 0 | K36: 3 | M36: =IF(OR($H36="",$I36=""),"",IF(OR(J36="",K36=""),-1,(IF(AND(J36=$H36,K36=$I36),5,IF(SIGN(J36-K36)=SIGN($H36-$I36),IF((J36-K36)=($H36-$I36),4,3),0)))*IF(L36="J",2,1))) -> 3 | N36: 0 | O36: 2 | Q36: =IF(OR($H36="",$I36=""),"",IF(OR(N36="",O36=""),-1,(IF(AND(N36=$H36,O36=$I36),5,IF(SIGN(N36-O36)=SIGN($H36-$I36),IF((N36-O36)=($H36-$I36),4,3),0)))*IF(P36="J",2,1))) -> 3 | R36: 0 | S36: 2 | U36: =IF(OR($H36="",$I36=""),"",IF(OR(R36="",S36=""),-1,(IF(AND(R36=$H36,S36=$I36),5,IF(SIGN(R36-S36)=SIGN($H36-$I36),IF((R36-S36)=($H36-$I36),4,3),0)))*IF(T36="J",2,1))) -> 3 | V36: Estadio BBVA, Monterrey
A37: 34 | B37: Sat, Jun 20 | C37: 12:00 | D37: F | E37: Netherlands | F37: Sweden | G37: L | H37: 5 | I37: 1 | J37: 2 | K37: 1 | M37: =IF(OR($H37="",$I37=""),"",IF(OR(J37="",K37=""),-1,(IF(AND(J37=$H37,K37=$I37),5,IF(SIGN(J37-K37)=SIGN($H37-$I37),IF((J37-K37)=($H37-$I37),4,3),0)))*IF(L37="J",2,1))) -> 3 | N37: 2 | O37: 2 | Q37: =IF(OR($H37="",$I37=""),"",IF(OR(N37="",O37=""),-1,(IF(AND(N37=$H37,O37=$I37),5,IF(SIGN(N37-O37)=SIGN($H37-$I37),IF((N37-O37)=($H37-$I37),4,3),0)))*IF(P37="J",2,1))) -> 0 | R37: 2 | S37: 2 | U37: =IF(OR($H37="",$I37=""),"",IF(OR(R37="",S37=""),-1,(IF(AND(R37=$H37,S37=$I37),5,IF(SIGN(R37-S37)=SIGN($H37-$I37),IF((R37-S37)=($H37-$I37),4,3),0)))*IF(T37="J",2,1))) -> 0 | V37: NRG Stadium, Houston
A38: 35 | B38: Sat, Jun 20 | C38: 15:00 | D38: E | E38: Germany | F38: Ivory Coast | G38: L | H38: 2 | I38: 1 | J38: 3 | K38: 1 | M38: =IF(OR($H38="",$I38=""),"",IF(OR(J38="",K38=""),-1,(IF(AND(J38=$H38,K38=$I38),5,IF(SIGN(J38-K38)=SIGN($H38-$I38),IF((J38-K38)=($H38-$I38),4,3),0)))*IF(L38="J",2,1))) -> 3 | N38: 2 | O38: 1 | Q38: =IF(OR($H38="",$I38=""),"",IF(OR(N38="",O38=""),-1,(IF(AND(N38=$H38,O38=$I38),5,IF(SIGN(N38-O38)=SIGN($H38-$I38),IF((N38-O38)=($H38-$I38),4,3),0)))*IF(P38="J",2,1))) -> 5 | R38: 3 | S38: 2 | U38: =IF(OR($H38="",$I38=""),"",IF(OR(R38="",S38=""),-1,(IF(AND(R38=$H38,S38=$I38),5,IF(SIGN(R38-S38)=SIGN($H38-$I38),IF((R38-S38)=($H38-$I38),4,3),0)))*IF(T38="J",2,1))) -> 4 | V38: BMO Field, Toronto
A39: 36 | B39: Sat, Jun 20 | C39: 19:00 | D39: E | E39: Ecuador | F39: Curaçao | G39: L | H39: 0 | I39: 0 | J39: 3 | K39: 1 | M39: =IF(OR($H39="",$I39=""),"",IF(OR(J39="",K39=""),-1,(IF(AND(J39=$H39,K39=$I39),5,IF(SIGN(J39-K39)=SIGN($H39-$I39),IF((J39-K39)=($H39-$I39),4,3),0)))*IF(L39="J",2,1))) -> 0 | N39: 3 | O39: 2 | Q39: =IF(OR($H39="",$I39=""),"",IF(OR(N39="",O39=""),-1,(IF(AND(N39=$H39,O39=$I39),5,IF(SIGN(N39-O39)=SIGN($H39-$I39),IF((N39-O39)=($H39-$I39),4,3),0)))*IF(P39="J",2,1))) -> 0 | R39: 3 | S39: 0 | U39: =IF(OR($H39="",$I39=""),"",IF(OR(R39="",S39=""),-1,(IF(AND(R39=$H39,S39=$I39),5,IF(SIGN(R39-S39)=SIGN($H39-$I39),IF((R39-S39)=($H39-$I39),4,3),0)))*IF(T39="J",2,1))) -> 0 | V39: Arrowhead Stadium, Kansas City
A40: 37 | B40: Sun, Jun 21 | C40: 11:00 | D40: H | E40: Spain | F40: Saudi Arabia | G40: L | H40: 5 | I40: 0 | J40: 3 | K40: 0 | L40: J | M40: =IF(OR($H40="",$I40=""),"",IF(OR(J40="",K40=""),-1,(IF(AND(J40=$H40,K40=$I40),5,IF(SIGN(J40-K40)=SIGN($H40-$I40),IF((J40-K40)=($H40-$I40),4,3),0)))*IF(L40="J",2,1))) -> 6 | N40: 2 | O40: 0 | P40: J | Q40: =IF(OR($H40="",$I40=""),"",IF(OR(N40="",O40=""),-1,(IF(AND(N40=$H40,O40=$I40),5,IF(SIGN(N40-O40)=SIGN($H40-$I40),IF((N40-O40)=($H40-$I40),4,3),0)))*IF(P40="J",2,1))) -> 6 | R40: 3 | S40: 0 | U40: =IF(OR($H40="",$I40=""),"",IF(OR(R40="",S40=""),-1,(IF(AND(R40=$H40,S40=$I40),5,IF(SIGN(R40-S40)=SIGN($H40-$I40),IF((R40-S40)=($H40-$I40),4,3),0)))*IF(T40="J",2,1))) -> 3 | V40: Mercedes-Benz Stadium, Atlanta
...

Sheet Knockout
A1: KNOCKOUT STAGE — teams, dates & scores auto-fill from results · then predict each scoreline (same rules, 'J' = Joker)
A2: MATCH | G2: ACTUAL | J2: GANESH | N2: SIDDHESH | R2: ANIKET
A3: # | B3: Round | C3: Date (auto) | D3: Stg | E3: Home | F3: Away | G3: Lock | H3: Act H | I3: Act A | J3: G H | K3: G A | L3: Jk | M3: G Pts | N3: S H | O3: S A | P3: Jk | Q3: S Pts | R3: A H | S3: A A | T3: Jk | U3: A Pts
A4: 73 | B4: Round of 32 | C4: 46201 | D4: R32 | M4: =IF(OR($H4="",$I4=""),"",IF(OR(J4="",K4=""),-1,(IF(AND(J4=$H4,K4=$I4),5,IF(SIGN(J4-K4)=SIGN($H4-$I4),IF((J4-K4)=($H4-$I4),4,3),0)))*IF(L4="J",2,1))) | Q4: =IF(OR($H4="",$I4=""),"",IF(OR(N4="",O4=""),-1,(IF(AND(N4=$H4,O4=$I4),5,IF(SIGN(N4-O4)=SIGN($H4-$I4),IF((N4-O4)=($H4-$I4),4,3),0)))*IF(P4="J",2,1))) | U4: =IF(OR($H4="",$I4=""),"",IF(OR(R4="",S4=""),-1,(IF(AND(R4=$H4,S4=$I4),5,IF(SIGN(R4-S4)=SIGN($H4-$I4),IF((R4-S4)=($H4-$I4),4,3),0)))*IF(T4="J",2,1)))
A5: 74 | B5: Round of 32 | C5: 46202 | D5: R32 | M5: =IF(OR($H5="",$I5=""),"",IF(OR(J5="",K5=""),-1,(IF(AND(J5=$H5,K5=$I5),5,IF(SIGN(J5-K5)=SIGN($H5-$I5),IF((J5-K5)=($H5-$I5),4,3),0)))*IF(L5="J",2,1))) | Q5: =IF(OR($H5="",$I5=""),"",IF(OR(N5="",O5=""),-1,(IF(AND(N5=$H5,O5=$I5),5,IF(SIGN(N5-O5)=SIGN($H5-$I5),IF((N5-O5)=($H5-$I5),4,3),0)))*IF(P5="J",2,1))) | U5: =IF(OR($H5="",$I5=""),"",IF(OR(R5="",S5=""),-1,(IF(AND(R5=$H5,S5=$I5),5,IF(SIGN(R5-S5)=SIGN($H5-$I5),IF((R5-S5)=($H5-$I5),4,3),0)))*IF(T5="J",2,1)))
A6: 75 | B6: Round of 32 | C6: 46202 | D6: R32 | M6: =IF(OR($H6="",$I6=""),"",IF(OR(J6="",K6=""),-1,(IF(AND(J6=$H6,K6=$I6),5,IF(SIGN(J6-K6)=SIGN($H6-$I6),IF((J6-K6)=($H6-$I6),4,3),0)))*IF(L6="J",2,1))) | Q6: =IF(OR($H6="",$I6=""),"",IF(OR(N6="",O6=""),-1,(IF(AND(N6=$H6,O6=$I6),5,IF(SIGN(N6-O6)=SIGN($H6-$I6),IF((N6-O6)=($H6-$I6),4,3),0)))*IF(P6="J",2,1))) | U6: =IF(OR($H6="",$I6=""),"",IF(OR(R6="",S6=""),-1,(IF(AND(R6=$H6,S6=$I6),5,IF(SIGN(R6-S6)=SIGN($H6-$I6),IF((R6-S6)=($H6-$I6),4,3),0)))*IF(T6="J",2,1)))
